2014-03-18 14:05:07 [10914] [CRITICAL] WORKER TIMEOUT (pid:10926)
2014-03-18 14:05:07 [10914] [CRITICAL] WORKER TIMEOUT (pid:10932)
2014-03-18 14:05:07 [10914] [CRITICAL] WORKER TIMEOUT (pid:10933)
2014-03-18 14:05:07 [10914] [CRITICAL] WORKER TIMEOUT (pid:10935)
2014-03-18 14:05:07 [10914] [CRITICAL] WORKER TIMEOUT (pid:10943)
2014-03-18 14:05:07 [10914] [CRITICAL] WORKER TIMEOUT (pid:10926)
2014-03-18 14:05:07 [10914] [CRITICAL] WORKER TIMEOUT (pid:10932)
2014-03-18 14:05:07 [10914] [CRITICAL] WORKER TIMEOUT (pid:10933)
2014-03-18 14:05:07 [10914] [CRITICAL] WORKER TIMEOUT (pid:10935)
2014-03-18 14:05:07 [10914] [CRITICAL] WORKER TIMEOUT (pid:10943)
2014-03-18 14:05:07 [10914] [CRITICAL] WORKER TIMEOUT (pid:10935)
2014-03-18 14:05:07 [10914] [CRITICAL] WORKER TIMEOUT (pid:10943)
ERROR:app:Exception on /raw-updates [GET]
Traceback (most recent call last):
  File "/home/tfb/FrameworkBenchmarks/installs/pypy/site-packages/Flask-0.10.1-py2.7.egg/flask/app.py", line 1817, in wsgi_app
    response = self.full_dispatch_request()
  File "/home/tfb/FrameworkBenchmarks/installs/pypy/site-packages/Flask-0.10.1-py2.7.egg/flask/app.py", line 1477, in full_dispatch_request
    rv = self.handle_user_exception(e)
  File "/home/tfb/FrameworkBenchmarks/installs/pypy/site-packages/Flask-0.10.1-py2.7.egg/flask/app.py", line 1381, in handle_user_exception
    reraise(exc_type, exc_value, tb)
  File "/home/tfb/FrameworkBenchmarks/installs/pypy/site-packages/Flask-0.10.1-py2.7.egg/flask/app.py", line 1475, in full_dispatch_request
    rv = self.dispatch_request()
  File "/home/tfb/FrameworkBenchmarks/installs/pypy/site-packages/Flask-0.10.1-py2.7.egg/flask/app.py", line 1461, in dispatch_request
    return self.view_functions[rule.endpoint](**req.view_args)
  File "/home/tfb/FrameworkBenchmarks/flask/app.py", line 152, in raw_updates
    (randomNumber, world['id']))
  File "/home/tfb/FrameworkBenchmarks/installs/pypy/site-packages/SQLAlchemy-0.8.3-py2.7.egg/sqlalchemy/engine/base.py", line 1613, in execute
    connection = self.contextual_connect(close_with_result=True)
  File "/home/tfb/FrameworkBenchmarks/installs/pypy/site-packages/SQLAlchemy-0.8.3-py2.7.egg/sqlalchemy/engine/base.py", line 1661, in contextual_connect
    self.pool.connect(),
  File "/home/tfb/FrameworkBenchmarks/installs/pypy/site-packages/SQLAlchemy-0.8.3-py2.7.egg/sqlalchemy/pool.py", line 272, in connect
    return _ConnectionFairy(self).checkout()
  File "/home/tfb/FrameworkBenchmarks/installs/pypy/site-packages/SQLAlchemy-0.8.3-py2.7.egg/sqlalchemy/pool.py", line 431, in __init__
    rec = self._connection_record = pool._do_get()
  File "/home/tfb/FrameworkBenchmarks/installs/pypy/site-packages/SQLAlchemy-0.8.3-py2.7.egg/sqlalchemy/pool.py", line 780, in _do_get
    (self.size(), self.overflow(), self._timeout))
TimeoutError: QueuePool limit of size 5 overflow 10 reached, connection timed out, timeout 30
ERROR:app:Exception on /raw-updates [GET]
Traceback (most recent call last):
  File "/home/tfb/FrameworkBenchmarks/installs/pypy/site-packages/Flask-0.10.1-py2.7.egg/flask/app.py", line 1817, in wsgi_app
    response = self.full_dispatch_request()
  File "/home/tfb/FrameworkBenchmarks/installs/pypy/site-packages/Flask-0.10.1-py2.7.egg/flask/app.py", line 1477, in full_dispatch_request
    rv = self.handle_user_exception(e)
  File "/home/tfb/FrameworkBenchmarks/installs/pypy/site-packages/Flask-0.10.1-py2.7.egg/flask/app.py", line 1381, in handle_user_exception
    reraise(exc_type, exc_value, tb)
  File "/home/tfb/FrameworkBenchmarks/installs/pypy/site-packages/Flask-0.10.1-py2.7.egg/flask/app.py", line 1475, in full_dispatch_request
    rv = self.dispatch_request()
  File "/home/tfb/FrameworkBenchmarks/installs/pypy/site-packages/Flask-0.10.1-py2.7.egg/flask/app.py", line 1461, in dispatch_request
    return self.view_functions[rule.endpoint](**req.view_args)
  File "/home/tfb/FrameworkBenchmarks/flask/app.py", line 152, in raw_updates
    (randomNumber, world['id']))
  File "/home/tfb/FrameworkBenchmarks/installs/pypy/site-packages/SQLAlchemy-0.8.3-py2.7.egg/sqlalchemy/engine/base.py", line 1613, in execute
    connection = self.contextual_connect(close_with_result=True)
  File "/home/tfb/FrameworkBenchmarks/installs/pypy/site-packages/SQLAlchemy-0.8.3-py2.7.egg/sqlalchemy/engine/base.py", line 1661, in contextual_connect
    self.pool.connect(),
  File "/home/tfb/FrameworkBenchmarks/installs/pypy/site-packages/SQLAlchemy-0.8.3-py2.7.egg/sqlalchemy/pool.py", line 272, in connect
    return _ConnectionFairy(self).checkout()
  File "/home/tfb/FrameworkBenchmarks/installs/pypy/site-packages/SQLAlchemy-0.8.3-py2.7.egg/sqlalchemy/pool.py", line 431, in __init__
    rec = self._connection_record = pool._do_get()
  File "/home/tfb/FrameworkBenchmarks/installs/pypy/site-packages/SQLAlchemy-0.8.3-py2.7.egg/sqlalchemy/pool.py", line 780, in _do_get
    (self.size(), self.overflow(), self._timeout))
TimeoutError: QueuePool limit of size 5 overflow 10 reached, connection timed out, timeout 30
ERROR:app:Exception on /raw-updates [GET]
Traceback (most recent call last):
  File "/home/tfb/FrameworkBenchmarks/installs/pypy/site-packages/Flask-0.10.1-py2.7.egg/flask/app.py", line 1817, in wsgi_app
    response = self.full_dispatch_request()
  File "/home/tfb/FrameworkBenchmarks/installs/pypy/site-packages/Flask-0.10.1-py2.7.egg/flask/app.py", line 1477, in full_dispatch_request
    rv = self.handle_user_exception(e)
  File "/home/tfb/FrameworkBenchmarks/installs/pypy/site-packages/Flask-0.10.1-py2.7.egg/flask/app.py", line 1381, in handle_user_exception
    reraise(exc_type, exc_value, tb)
  File "/home/tfb/FrameworkBenchmarks/installs/pypy/site-packages/Flask-0.10.1-py2.7.egg/flask/app.py", line 1475, in full_dispatch_request
    rv = self.dispatch_request()
  File "/home/tfb/FrameworkBenchmarks/installs/pypy/site-packages/Flask-0.10.1-py2.7.egg/flask/app.py", line 1461, in dispatch_request
    return self.view_functions[rule.endpoint](**req.view_args)
  File "/home/tfb/FrameworkBenchmarks/flask/app.py", line 152, in raw_updates
    (randomNumber, world['id']))
  File "/home/tfb/FrameworkBenchmarks/installs/pypy/site-packages/SQLAlchemy-0.8.3-py2.7.egg/sqlalchemy/engine/base.py", line 1613, in execute
    connection = self.contextual_connect(close_with_result=True)
  File "/home/tfb/FrameworkBenchmarks/installs/pypy/site-packages/SQLAlchemy-0.8.3-py2.7.egg/sqlalchemy/engine/base.py", line 1661, in contextual_connect
    self.pool.connect(),
  File "/home/tfb/FrameworkBenchmarks/installs/pypy/site-packages/SQLAlchemy-0.8.3-py2.7.egg/sqlalchemy/pool.py", line 272, in connect
    return _ConnectionFairy(self).checkout()
  File "/home/tfb/FrameworkBenchmarks/installs/pypy/site-packages/SQLAlchemy-0.8.3-py2.7.egg/sqlalchemy/pool.py", line 431, in __init__
    rec = self._connection_record = pool._do_get()
  File "/home/tfb/FrameworkBenchmarks/installs/pypy/site-packages/SQLAlchemy-0.8.3-py2.7.egg/sqlalchemy/pool.py", line 780, in _do_get
    (self.size(), self.overflow(), self._timeout))
TimeoutError: QueuePool limit of size 5 overflow 10 reached, connection timed out, timeout 30
ERROR:app:Exception on /raw-updates [GET]
Traceback (most recent call last):
  File "/home/tfb/FrameworkBenchmarks/installs/pypy/site-packages/Flask-0.10.1-py2.7.egg/flask/app.py", line 1817, in wsgi_app
    response = self.full_dispatch_request()
  File "/home/tfb/FrameworkBenchmarks/installs/pypy/site-packages/Flask-0.10.1-py2.7.egg/flask/app.py", line 1477, in full_dispatch_request
    rv = self.handle_user_exception(e)
  File "/home/tfb/FrameworkBenchmarks/installs/pypy/site-packages/Flask-0.10.1-py2.7.egg/flask/app.py", line 1381, in handle_user_exception
    reraise(exc_type, exc_value, tb)
  File "/home/tfb/FrameworkBenchmarks/installs/pypy/site-packages/Flask-0.10.1-py2.7.egg/flask/app.py", line 1475, in full_dispatch_request
    rv = self.dispatch_request()
  File "/home/tfb/FrameworkBenchmarks/installs/pypy/site-packages/Flask-0.10.1-py2.7.egg/flask/app.py", line 1461, in dispatch_request
    return self.view_functions[rule.endpoint](**req.view_args)
  File "/home/tfb/FrameworkBenchmarks/flask/app.py", line 152, in raw_updates
    (randomNumber, world['id']))
  File "/home/tfb/FrameworkBenchmarks/installs/pypy/site-packages/SQLAlchemy-0.8.3-py2.7.egg/sqlalchemy/engine/base.py", line 1613, in execute
    connection = self.contextual_connect(close_with_result=True)
  File "/home/tfb/FrameworkBenchmarks/installs/pypy/site-packages/SQLAlchemy-0.8.3-py2.7.egg/sqlalchemy/engine/base.py", line 1661, in contextual_connect
    self.pool.connect(),
  File "/home/tfb/FrameworkBenchmarks/installs/pypy/site-packages/SQLAlchemy-0.8.3-py2.7.egg/sqlalchemy/pool.py", line 272, in connect
    return _ConnectionFairy(self).checkout()
  File "/home/tfb/FrameworkBenchmarks/installs/pypy/site-packages/SQLAlchemy-0.8.3-py2.7.egg/sqlalchemy/pool.py", line 431, in __init__
    rec = self._connection_record = pool._do_get()
  File "/home/tfb/FrameworkBenchmarks/installs/pypy/site-packages/SQLAlchemy-0.8.3-py2.7.egg/sqlalchemy/pool.py", line 780, in _do_get
    (self.size(), self.overflow(), self._timeout))
TimeoutError: QueuePool limit of size 5 overflow 10 reached, connection timed out, timeout 30
ERROR:app:Exception on /raw-updates [GET]
Traceback (most recent call last):
  File "/home/tfb/FrameworkBenchmarks/installs/pypy/site-packages/Flask-0.10.1-py2.7.egg/flask/app.py", line 1817, in wsgi_app
    response = self.full_dispatch_request()
  File "/home/tfb/FrameworkBenchmarks/installs/pypy/site-packages/Flask-0.10.1-py2.7.egg/flask/app.py", line 1477, in full_dispatch_request
    rv = self.handle_user_exception(e)
  File "/home/tfb/FrameworkBenchmarks/installs/pypy/site-packages/Flask-0.10.1-py2.7.egg/flask/app.py", line 1381, in handle_user_exception
    reraise(exc_type, exc_value, tb)
  File "/home/tfb/FrameworkBenchmarks/installs/pypy/site-packages/Flask-0.10.1-py2.7.egg/flask/app.py", line 1475, in full_dispatch_request
    rv = self.dispatch_request()
  File "/home/tfb/FrameworkBenchmarks/installs/pypy/site-packages/Flask-0.10.1-py2.7.egg/flask/app.py", line 1461, in dispatch_request
    return self.view_functions[rule.endpoint](**req.view_args)
  File "/home/tfb/FrameworkBenchmarks/flask/app.py", line 152, in raw_updates
    (randomNumber, world['id']))
  File "/home/tfb/FrameworkBenchmarks/installs/pypy/site-packages/SQLAlchemy-0.8.3-py2.7.egg/sqlalchemy/engine/base.py", line 1613, in execute
    connection = self.contextual_connect(close_with_result=True)
  File "/home/tfb/FrameworkBenchmarks/installs/pypy/site-packages/SQLAlchemy-0.8.3-py2.7.egg/sqlalchemy/engine/base.py", line 1661, in contextual_connect
    self.pool.connect(),
  File "/home/tfb/FrameworkBenchmarks/installs/pypy/site-packages/SQLAlchemy-0.8.3-py2.7.egg/sqlalchemy/pool.py", line 272, in connect
    return _ConnectionFairy(self).checkout()
  File "/home/tfb/FrameworkBenchmarks/installs/pypy/site-packages/SQLAlchemy-0.8.3-py2.7.egg/sqlalchemy/pool.py", line 431, in __init__
    rec = self._connection_record = pool._do_get()
  File "/home/tfb/FrameworkBenchmarks/installs/pypy/site-packages/SQLAlchemy-0.8.3-py2.7.egg/sqlalchemy/pool.py", line 780, in _do_get
    (self.size(), self.overflow(), self._timeout))
TimeoutError: QueuePool limit of size 5 overflow 10 reached, connection timed out, timeout 30
ERROR:app:Exception on /raw-updates [GET]
Traceback (most recent call last):
  File "/home/tfb/FrameworkBenchmarks/installs/pypy/site-packages/Flask-0.10.1-py2.7.egg/flask/app.py", line 1817, in wsgi_app
    response = self.full_dispatch_request()
  File "/home/tfb/FrameworkBenchmarks/installs/pypy/site-packages/Flask-0.10.1-py2.7.egg/flask/app.py", line 1477, in full_dispatch_request
    rv = self.handle_user_exception(e)
  File "/home/tfb/FrameworkBenchmarks/installs/pypy/site-packages/Flask-0.10.1-py2.7.egg/flask/app.py", line 1381, in handle_user_exception
    reraise(exc_type, exc_value, tb)
  File "/home/tfb/FrameworkBenchmarks/installs/pypy/site-packages/Flask-0.10.1-py2.7.egg/flask/app.py", line 1475, in full_dispatch_request
    rv = self.dispatch_request()
  File "/home/tfb/FrameworkBenchmarks/installs/pypy/site-packages/Flask-0.10.1-py2.7.egg/flask/app.py", line 1461, in dispatch_request
    return self.view_functions[rule.endpoint](**req.view_args)
  File "/home/tfb/FrameworkBenchmarks/flask/app.py", line 152, in raw_updates
    (randomNumber, world['id']))
  File "/home/tfb/FrameworkBenchmarks/installs/pypy/site-packages/SQLAlchemy-0.8.3-py2.7.egg/sqlalchemy/engine/base.py", line 1613, in execute
    connection = self.contextual_connect(close_with_result=True)
  File "/home/tfb/FrameworkBenchmarks/installs/pypy/site-packages/SQLAlchemy-0.8.3-py2.7.egg/sqlalchemy/engine/base.py", line 1661, in contextual_connect
    self.pool.connect(),
  File "/home/tfb/FrameworkBenchmarks/installs/pypy/site-packages/SQLAlchemy-0.8.3-py2.7.egg/sqlalchemy/pool.py", line 272, in connect
    return _ConnectionFairy(self).checkout()
  File "/home/tfb/FrameworkBenchmarks/installs/pypy/site-packages/SQLAlchemy-0.8.3-py2.7.egg/sqlalchemy/pool.py", line 431, in __init__
    rec = self._connection_record = pool._do_get()
  File "/home/tfb/FrameworkBenchmarks/installs/pypy/site-packages/SQLAlchemy-0.8.3-py2.7.egg/sqlalchemy/pool.py", line 780, in _do_get
    (self.size(), self.overflow(), self._timeout))
TimeoutError: QueuePool limit of size 5 overflow 10 reached, connection timed out, timeout 30
ERROR:app:Exception on /raw-updates [GET]
Traceback (most recent call last):
  File "/home/tfb/FrameworkBenchmarks/installs/pypy/site-packages/Flask-0.10.1-py2.7.egg/flask/app.py", line 1817, in wsgi_app
    response = self.full_dispatch_request()
  File "/home/tfb/FrameworkBenchmarks/installs/pypy/site-packages/Flask-0.10.1-py2.7.egg/flask/app.py", line 1477, in full_dispatch_request
    rv = self.handle_user_exception(e)
  File "/home/tfb/FrameworkBenchmarks/installs/pypy/site-packages/Flask-0.10.1-py2.7.egg/flask/app.py", line 1381, in handle_user_exception
    reraise(exc_type, exc_value, tb)
  File "/home/tfb/FrameworkBenchmarks/installs/pypy/site-packages/Flask-0.10.1-py2.7.egg/flask/app.py", line 1475, in full_dispatch_request
    rv = self.dispatch_request()
  File "/home/tfb/FrameworkBenchmarks/installs/pypy/site-packages/Flask-0.10.1-py2.7.egg/flask/app.py", line 1461, in dispatch_request
    return self.view_functions[rule.endpoint](**req.view_args)
  File "/home/tfb/FrameworkBenchmarks/flask/app.py", line 152, in raw_updates
    (randomNumber, world['id']))
  File "/home/tfb/FrameworkBenchmarks/installs/pypy/site-packages/SQLAlchemy-0.8.3-py2.7.egg/sqlalchemy/engine/base.py", line 1613, in execute
    connection = self.contextual_connect(close_with_result=True)
  File "/home/tfb/FrameworkBenchmarks/installs/pypy/site-packages/SQLAlchemy-0.8.3-py2.7.egg/sqlalchemy/engine/base.py", line 1661, in contextual_connect
    self.pool.connect(),
  File "/home/tfb/FrameworkBenchmarks/installs/pypy/site-packages/SQLAlchemy-0.8.3-py2.7.egg/sqlalchemy/pool.py", line 272, in connect
    return _ConnectionFairy(self).checkout()
  File "/home/tfb/FrameworkBenchmarks/installs/pypy/site-packages/SQLAlchemy-0.8.3-py2.7.egg/sqlalchemy/pool.py", line 431, in __init__
    rec = self._connection_record = pool._do_get()
  File "/home/tfb/FrameworkBenchmarks/installs/pypy/site-packages/SQLAlchemy-0.8.3-py2.7.egg/sqlalchemy/pool.py", line 780, in _do_get
    (self.size(), self.overflow(), self._timeout))
TimeoutError: QueuePool limit of size 5 overflow 10 reached, connection timed out, timeout 30
ERROR:app:Exception on /raw-updates [GET]
Traceback (most recent call last):
  File "/home/tfb/FrameworkBenchmarks/installs/pypy/site-packages/Flask-0.10.1-py2.7.egg/flask/app.py", line 1817, in wsgi_app
    response = self.full_dispatch_request()
  File "/home/tfb/FrameworkBenchmarks/installs/pypy/site-packages/Flask-0.10.1-py2.7.egg/flask/app.py", line 1477, in full_dispatch_request
    rv = self.handle_user_exception(e)
  File "/home/tfb/FrameworkBenchmarks/installs/pypy/site-packages/Flask-0.10.1-py2.7.egg/flask/app.py", line 1381, in handle_user_exception
    reraise(exc_type, exc_value, tb)
  File "/home/tfb/FrameworkBenchmarks/installs/pypy/site-packages/Flask-0.10.1-py2.7.egg/flask/app.py", line 1475, in full_dispatch_request
    rv = self.dispatch_request()
  File "/home/tfb/FrameworkBenchmarks/installs/pypy/site-packages/Flask-0.10.1-py2.7.egg/flask/app.py", line 1461, in dispatch_request
    return self.view_functions[rule.endpoint](**req.view_args)
  File "/home/tfb/FrameworkBenchmarks/flask/app.py", line 152, in raw_updates
    (randomNumber, world['id']))
  File "/home/tfb/FrameworkBenchmarks/installs/pypy/site-packages/SQLAlchemy-0.8.3-py2.7.egg/sqlalchemy/engine/base.py", line 1613, in execute
    connection = self.contextual_connect(close_with_result=True)
  File "/home/tfb/FrameworkBenchmarks/installs/pypy/site-packages/SQLAlchemy-0.8.3-py2.7.egg/sqlalchemy/engine/base.py", line 1661, in contextual_connect
    self.pool.connect(),
  File "/home/tfb/FrameworkBenchmarks/installs/pypy/site-packages/SQLAlchemy-0.8.3-py2.7.egg/sqlalchemy/pool.py", line 272, in connect
    return _ConnectionFairy(self).checkout()
  File "/home/tfb/FrameworkBenchmarks/installs/pypy/site-packages/SQLAlchemy-0.8.3-py2.7.egg/sqlalchemy/pool.py", line 431, in __init__
    rec = self._connection_record = pool._do_get()
  File "/home/tfb/FrameworkBenchmarks/installs/pypy/site-packages/SQLAlchemy-0.8.3-py2.7.egg/sqlalchemy/pool.py", line 780, in _do_get
    (self.size(), self.overflow(), self._timeout))
TimeoutError: QueuePool limit of size 5 overflow 10 reached, connection timed out, timeout 30
ERROR:app:Exception on /raw-updates [GET]
Traceback (most recent call last):
  File "/home/tfb/FrameworkBenchmarks/installs/pypy/site-packages/Flask-0.10.1-py2.7.egg/flask/app.py", line 1817, in wsgi_app
    response = self.full_dispatch_request()
  File "/home/tfb/FrameworkBenchmarks/installs/pypy/site-packages/Flask-0.10.1-py2.7.egg/flask/app.py", line 1477, in full_dispatch_request
    rv = self.handle_user_exception(e)
  File "/home/tfb/FrameworkBenchmarks/installs/pypy/site-packages/Flask-0.10.1-py2.7.egg/flask/app.py", line 1381, in handle_user_exception
    reraise(exc_type, exc_value, tb)
  File "/home/tfb/FrameworkBenchmarks/installs/pypy/site-packages/Flask-0.10.1-py2.7.egg/flask/app.py", line 1475, in full_dispatch_request
    rv = self.dispatch_request()
  File "/home/tfb/FrameworkBenchmarks/installs/pypy/site-packages/Flask-0.10.1-py2.7.egg/flask/app.py", line 1461, in dispatch_request
    return self.view_functions[rule.endpoint](**req.view_args)
  File "/home/tfb/FrameworkBenchmarks/flask/app.py", line 152, in raw_updates
    (randomNumber, world['id']))
  File "/home/tfb/FrameworkBenchmarks/installs/pypy/site-packages/SQLAlchemy-0.8.3-py2.7.egg/sqlalchemy/engine/base.py", line 1613, in execute
    connection = self.contextual_connect(close_with_result=True)
  File "/home/tfb/FrameworkBenchmarks/installs/pypy/site-packages/SQLAlchemy-0.8.3-py2.7.egg/sqlalchemy/engine/base.py", line 1661, in contextual_connect
    self.pool.connect(),
  File "/home/tfb/FrameworkBenchmarks/installs/pypy/site-packages/SQLAlchemy-0.8.3-py2.7.egg/sqlalchemy/pool.py", line 272, in connect
    return _ConnectionFairy(self).checkout()
  File "/home/tfb/FrameworkBenchmarks/installs/pypy/site-packages/SQLAlchemy-0.8.3-py2.7.egg/sqlalchemy/pool.py", line 431, in __init__
    rec = self._connection_record = pool._do_get()
  File "/home/tfb/FrameworkBenchmarks/installs/pypy/site-packages/SQLAlchemy-0.8.3-py2.7.egg/sqlalchemy/pool.py", line 780, in _do_get
    (self.size(), self.overflow(), self._timeout))
TimeoutError: QueuePool limit of size 5 overflow 10 reached, connection timed out, timeout 30
ERROR:app:Exception on /raw-updates [GET]
Traceback (most recent call last):
  File "/home/tfb/FrameworkBenchmarks/installs/pypy/site-packages/Flask-0.10.1-py2.7.egg/flask/app.py", line 1817, in wsgi_app
    response = self.full_dispatch_request()
  File "/home/tfb/FrameworkBenchmarks/installs/pypy/site-packages/Flask-0.10.1-py2.7.egg/flask/app.py", line 1477, in full_dispatch_request
    rv = self.handle_user_exception(e)
  File "/home/tfb/FrameworkBenchmarks/installs/pypy/site-packages/Flask-0.10.1-py2.7.egg/flask/app.py", line 1381, in handle_user_exception
    reraise(exc_type, exc_value, tb)
  File "/home/tfb/FrameworkBenchmarks/installs/pypy/site-packages/Flask-0.10.1-py2.7.egg/flask/app.py", line 1475, in full_dispatch_request
    rv = self.dispatch_request()
  File "/home/tfb/FrameworkBenchmarks/installs/pypy/site-packages/Flask-0.10.1-py2.7.egg/flask/app.py", line 1461, in dispatch_request
    return self.view_functions[rule.endpoint](**req.view_args)
  File "/home/tfb/FrameworkBenchmarks/flask/app.py", line 152, in raw_updates
    (randomNumber, world['id']))
  File "/home/tfb/FrameworkBenchmarks/installs/pypy/site-packages/SQLAlchemy-0.8.3-py2.7.egg/sqlalchemy/engine/base.py", line 1613, in execute
    connection = self.contextual_connect(close_with_result=True)
  File "/home/tfb/FrameworkBenchmarks/installs/pypy/site-packages/SQLAlchemy-0.8.3-py2.7.egg/sqlalchemy/engine/base.py", line 1661, in contextual_connect
    self.pool.connect(),
  File "/home/tfb/FrameworkBenchmarks/installs/pypy/site-packages/SQLAlchemy-0.8.3-py2.7.egg/sqlalchemy/pool.py", line 272, in connect
    return _ConnectionFairy(self).checkout()
  File "/home/tfb/FrameworkBenchmarks/installs/pypy/site-packages/SQLAlchemy-0.8.3-py2.7.egg/sqlalchemy/pool.py", line 431, in __init__
    rec = self._connection_record = pool._do_get()
  File "/home/tfb/FrameworkBenchmarks/installs/pypy/site-packages/SQLAlchemy-0.8.3-py2.7.egg/sqlalchemy/pool.py", line 780, in _do_get
    (self.size(), self.overflow(), self._timeout))
TimeoutError: QueuePool limit of size 5 overflow 10 reached, connection timed out, timeout 30
ERROR:app:Exception on /raw-updates [GET]
Traceback (most recent call last):
  File "/home/tfb/FrameworkBenchmarks/installs/pypy/site-packages/Flask-0.10.1-py2.7.egg/flask/app.py", line 1817, in wsgi_app
    response = self.full_dispatch_request()
  File "/home/tfb/FrameworkBenchmarks/installs/pypy/site-packages/Flask-0.10.1-py2.7.egg/flask/app.py", line 1477, in full_dispatch_request
    rv = self.handle_user_exception(e)
  File "/home/tfb/FrameworkBenchmarks/installs/pypy/site-packages/Flask-0.10.1-py2.7.egg/flask/app.py", line 1381, in handle_user_exception
    reraise(exc_type, exc_value, tb)
  File "/home/tfb/FrameworkBenchmarks/installs/pypy/site-packages/Flask-0.10.1-py2.7.egg/flask/app.py", line 1475, in full_dispatch_request
    rv = self.dispatch_request()
  File "/home/tfb/FrameworkBenchmarks/installs/pypy/site-packages/Flask-0.10.1-py2.7.egg/flask/app.py", line 1461, in dispatch_request
    return self.view_functions[rule.endpoint](**req.view_args)
  File "/home/tfb/FrameworkBenchmarks/flask/app.py", line 152, in raw_updates
    (randomNumber, world['id']))
  File "/home/tfb/FrameworkBenchmarks/installs/pypy/site-packages/SQLAlchemy-0.8.3-py2.7.egg/sqlalchemy/engine/base.py", line 1613, in execute
    connection = self.contextual_connect(close_with_result=True)
  File "/home/tfb/FrameworkBenchmarks/installs/pypy/site-packages/SQLAlchemy-0.8.3-py2.7.egg/sqlalchemy/engine/base.py", line 1661, in contextual_connect
    self.pool.connect(),
  File "/home/tfb/FrameworkBenchmarks/installs/pypy/site-packages/SQLAlchemy-0.8.3-py2.7.egg/sqlalchemy/pool.py", line 272, in connect
    return _ConnectionFairy(self).checkout()
  File "/home/tfb/FrameworkBenchmarks/installs/pypy/site-packages/SQLAlchemy-0.8.3-py2.7.egg/sqlalchemy/pool.py", line 431, in __init__
    rec = self._connection_record = pool._do_get()
  File "/home/tfb/FrameworkBenchmarks/installs/pypy/site-packages/SQLAlchemy-0.8.3-py2.7.egg/sqlalchemy/pool.py", line 780, in _do_get
    (self.size(), self.overflow(), self._timeout))
TimeoutError: QueuePool limit of size 5 overflow 10 reached, connection timed out, timeout 30
ERROR:app:Exception on /raw-updates [GET]
Traceback (most recent call last):
  File "/home/tfb/FrameworkBenchmarks/installs/pypy/site-packages/Flask-0.10.1-py2.7.egg/flask/app.py", line 1817, in wsgi_app
    response = self.full_dispatch_request()
  File "/home/tfb/FrameworkBenchmarks/installs/pypy/site-packages/Flask-0.10.1-py2.7.egg/flask/app.py", line 1477, in full_dispatch_request
    rv = self.handle_user_exception(e)
  File "/home/tfb/FrameworkBenchmarks/installs/pypy/site-packages/Flask-0.10.1-py2.7.egg/flask/app.py", line 1381, in handle_user_exception
    reraise(exc_type, exc_value, tb)
  File "/home/tfb/FrameworkBenchmarks/installs/pypy/site-packages/Flask-0.10.1-py2.7.egg/flask/app.py", line 1475, in full_dispatch_request
    rv = self.dispatch_request()
  File "/home/tfb/FrameworkBenchmarks/installs/pypy/site-packages/Flask-0.10.1-py2.7.egg/flask/app.py", line 1461, in dispatch_request
    return self.view_functions[rule.endpoint](**req.view_args)
  File "/home/tfb/FrameworkBenchmarks/flask/app.py", line 152, in raw_updates
    (randomNumber, world['id']))
  File "/home/tfb/FrameworkBenchmarks/installs/pypy/site-packages/SQLAlchemy-0.8.3-py2.7.egg/sqlalchemy/engine/base.py", line 1613, in execute
    connection = self.contextual_connect(close_with_result=True)
  File "/home/tfb/FrameworkBenchmarks/installs/pypy/site-packages/SQLAlchemy-0.8.3-py2.7.egg/sqlalchemy/engine/base.py", line 1661, in contextual_connect
    self.pool.connect(),
  File "/home/tfb/FrameworkBenchmarks/installs/pypy/site-packages/SQLAlchemy-0.8.3-py2.7.egg/sqlalchemy/pool.py", line 272, in connect
    return _ConnectionFairy(self).checkout()
  File "/home/tfb/FrameworkBenchmarks/installs/pypy/site-packages/SQLAlchemy-0.8.3-py2.7.egg/sqlalchemy/pool.py", line 431, in __init__
    rec = self._connection_record = pool._do_get()
  File "/home/tfb/FrameworkBenchmarks/installs/pypy/site-packages/SQLAlchemy-0.8.3-py2.7.egg/sqlalchemy/pool.py", line 780, in _do_get
    (self.size(), self.overflow(), self._timeout))
TimeoutError: QueuePool limit of size 5 overflow 10 reached, connection timed out, timeout 30
ERROR:app:Exception on /raw-updates [GET]
Traceback (most recent call last):
  File "/home/tfb/FrameworkBenchmarks/installs/pypy/site-packages/Flask-0.10.1-py2.7.egg/flask/app.py", line 1817, in wsgi_app
    response = self.full_dispatch_request()
  File "/home/tfb/FrameworkBenchmarks/installs/pypy/site-packages/Flask-0.10.1-py2.7.egg/flask/app.py", line 1477, in full_dispatch_request
    rv = self.handle_user_exception(e)
  File "/home/tfb/FrameworkBenchmarks/installs/pypy/site-packages/Flask-0.10.1-py2.7.egg/flask/app.py", line 1381, in handle_user_exception
    reraise(exc_type, exc_value, tb)
  File "/home/tfb/FrameworkBenchmarks/installs/pypy/site-packages/Flask-0.10.1-py2.7.egg/flask/app.py", line 1475, in full_dispatch_request
    rv = self.dispatch_request()
  File "/home/tfb/FrameworkBenchmarks/installs/pypy/site-packages/Flask-0.10.1-py2.7.egg/flask/app.py", line 1461, in dispatch_request
    return self.view_functions[rule.endpoint](**req.view_args)
  File "/home/tfb/FrameworkBenchmarks/flask/app.py", line 152, in raw_updates
    (randomNumber, world['id']))
  File "/home/tfb/FrameworkBenchmarks/installs/pypy/site-packages/SQLAlchemy-0.8.3-py2.7.egg/sqlalchemy/engine/base.py", line 1613, in execute
    connection = self.contextual_connect(close_with_result=True)
  File "/home/tfb/FrameworkBenchmarks/installs/pypy/site-packages/SQLAlchemy-0.8.3-py2.7.egg/sqlalchemy/engine/base.py", line 1661, in contextual_connect
    self.pool.connect(),
  File "/home/tfb/FrameworkBenchmarks/installs/pypy/site-packages/SQLAlchemy-0.8.3-py2.7.egg/sqlalchemy/pool.py", line 272, in connect
    return _ConnectionFairy(self).checkout()
  File "/home/tfb/FrameworkBenchmarks/installs/pypy/site-packages/SQLAlchemy-0.8.3-py2.7.egg/sqlalchemy/pool.py", line 431, in __init__
    rec = self._connection_record = pool._do_get()
  File "/home/tfb/FrameworkBenchmarks/installs/pypy/site-packages/SQLAlchemy-0.8.3-py2.7.egg/sqlalchemy/pool.py", line 780, in _do_get
    (self.size(), self.overflow(), self._timeout))
TimeoutError: QueuePool limit of size 5 overflow 10 reached, connection timed out, timeout 30
ERROR:app:Exception on /raw-updates [GET]
Traceback (most recent call last):
  File "/home/tfb/FrameworkBenchmarks/installs/pypy/site-packages/Flask-0.10.1-py2.7.egg/flask/app.py", line 1817, in wsgi_app
    response = self.full_dispatch_request()
  File "/home/tfb/FrameworkBenchmarks/installs/pypy/site-packages/Flask-0.10.1-py2.7.egg/flask/app.py", line 1477, in full_dispatch_request
    rv = self.handle_user_exception(e)
  File "/home/tfb/FrameworkBenchmarks/installs/pypy/site-packages/Flask-0.10.1-py2.7.egg/flask/app.py", line 1381, in handle_user_exception
    reraise(exc_type, exc_value, tb)
  File "/home/tfb/FrameworkBenchmarks/installs/pypy/site-packages/Flask-0.10.1-py2.7.egg/flask/app.py", line 1475, in full_dispatch_request
    rv = self.dispatch_request()
  File "/home/tfb/FrameworkBenchmarks/installs/pypy/site-packages/Flask-0.10.1-py2.7.egg/flask/app.py", line 1461, in dispatch_request
    return self.view_functions[rule.endpoint](**req.view_args)
  File "/home/tfb/FrameworkBenchmarks/flask/app.py", line 152, in raw_updates
    (randomNumber, world['id']))
  File "/home/tfb/FrameworkBenchmarks/installs/pypy/site-packages/SQLAlchemy-0.8.3-py2.7.egg/sqlalchemy/engine/base.py", line 1613, in execute
    connection = self.contextual_connect(close_with_result=True)
  File "/home/tfb/FrameworkBenchmarks/installs/pypy/site-packages/SQLAlchemy-0.8.3-py2.7.egg/sqlalchemy/engine/base.py", line 1661, in contextual_connect
    self.pool.connect(),
  File "/home/tfb/FrameworkBenchmarks/installs/pypy/site-packages/SQLAlchemy-0.8.3-py2.7.egg/sqlalchemy/pool.py", line 272, in connect
    return _ConnectionFairy(self).checkout()
  File "/home/tfb/FrameworkBenchmarks/installs/pypy/site-packages/SQLAlchemy-0.8.3-py2.7.egg/sqlalchemy/pool.py", line 431, in __init__
    rec = self._connection_record = pool._do_get()
  File "/home/tfb/FrameworkBenchmarks/installs/pypy/site-packages/SQLAlchemy-0.8.3-py2.7.egg/sqlalchemy/pool.py", line 780, in _do_get
    (self.size(), self.overflow(), self._timeout))
TimeoutError: QueuePool limit of size 5 overflow 10 reached, connection timed out, timeout 30
ERROR:tornado.access:500 GET /raw-updates?queries=2 (172.16.98.98) 30146.44ms
ERROR:tornado.access:500 GET /raw-updates?queries=2 (172.16.98.98) 30133.27ms
ERROR:tornado.access:500 GET /raw-updates?queries=2 (172.16.98.98) 30144.12ms
ERROR:tornado.access:500 GET /raw-updates?queries=2 (172.16.98.98) 30117.27ms
ERROR:tornado.access:500 GET /raw-updates?queries=2 (172.16.98.98) 30121.84ms
ERROR:tornado.access:500 GET /raw-updates?queries=2 (172.16.98.98) 30132.74ms
ERROR:tornado.access:500 GET /raw-updates?queries=2 (172.16.98.98) 30108.05ms
ERROR:tornado.access:500 GET /raw-updates?queries=2 (172.16.98.98) 30114.51ms
ERROR:app:Exception on /raw-updates [GET]
Traceback (most recent call last):
  File "/home/tfb/FrameworkBenchmarks/installs/pypy/site-packages/Flask-0.10.1-py2.7.egg/flask/app.py", line 1817, in wsgi_app
    response = self.full_dispatch_request()
  File "/home/tfb/FrameworkBenchmarks/installs/pypy/site-packages/Flask-0.10.1-py2.7.egg/flask/app.py", line 1477, in full_dispatch_request
    rv = self.handle_user_exception(e)
  File "/home/tfb/FrameworkBenchmarks/installs/pypy/site-packages/Flask-0.10.1-py2.7.egg/flask/app.py", line 1381, in handle_user_exception
    reraise(exc_type, exc_value, tb)
  File "/home/tfb/FrameworkBenchmarks/installs/pypy/site-packages/Flask-0.10.1-py2.7.egg/flask/app.py", line 1475, in full_dispatch_request
    rv = self.dispatch_request()
  File "/home/tfb/FrameworkBenchmarks/installs/pypy/site-packages/Flask-0.10.1-py2.7.egg/flask/app.py", line 1461, in dispatch_request
    return self.view_functions[rule.endpoint](**req.view_args)
  File "/home/tfb/FrameworkBenchmarks/flask/app.py", line 152, in raw_updates
    (randomNumber, world['id']))
  File "/home/tfb/FrameworkBenchmarks/installs/pypy/site-packages/SQLAlchemy-0.8.3-py2.7.egg/sqlalchemy/engine/base.py", line 1613, in execute
    connection = self.contextual_connect(close_with_result=True)
  File "/home/tfb/FrameworkBenchmarks/installs/pypy/site-packages/SQLAlchemy-0.8.3-py2.7.egg/sqlalchemy/engine/base.py", line 1661, in contextual_connect
    self.pool.connect(),
  File "/home/tfb/FrameworkBenchmarks/installs/pypy/site-packages/SQLAlchemy-0.8.3-py2.7.egg/sqlalchemy/pool.py", line 272, in connect
    return _ConnectionFairy(self).checkout()
  File "/home/tfb/FrameworkBenchmarks/installs/pypy/site-packages/SQLAlchemy-0.8.3-py2.7.egg/sqlalchemy/pool.py", line 431, in __init__
    rec = self._connection_record = pool._do_get()
  File "/home/tfb/FrameworkBenchmarks/installs/pypy/site-packages/SQLAlchemy-0.8.3-py2.7.egg/sqlalchemy/pool.py", line 780, in _do_get
    (self.size(), self.overflow(), self._timeout))
TimeoutError: QueuePool limit of size 5 overflow 10 reached, connection timed out, timeout 30
ERROR:app:Exception on /raw-updates [GET]
Traceback (most recent call last):
  File "/home/tfb/FrameworkBenchmarks/installs/pypy/site-packages/Flask-0.10.1-py2.7.egg/flask/app.py", line 1817, in wsgi_app
    response = self.full_dispatch_request()
  File "/home/tfb/FrameworkBenchmarks/installs/pypy/site-packages/Flask-0.10.1-py2.7.egg/flask/app.py", line 1477, in full_dispatch_request
    rv = self.handle_user_exception(e)
  File "/home/tfb/FrameworkBenchmarks/installs/pypy/site-packages/Flask-0.10.1-py2.7.egg/flask/app.py", line 1381, in handle_user_exception
    reraise(exc_type, exc_value, tb)
  File "/home/tfb/FrameworkBenchmarks/installs/pypy/site-packages/Flask-0.10.1-py2.7.egg/flask/app.py", line 1475, in full_dispatch_request
    rv = self.dispatch_request()
  File "/home/tfb/FrameworkBenchmarks/installs/pypy/site-packages/Flask-0.10.1-py2.7.egg/flask/app.py", line 1461, in dispatch_request
    return self.view_functions[rule.endpoint](**req.view_args)
  File "/home/tfb/FrameworkBenchmarks/flask/app.py", line 152, in raw_updates
    (randomNumber, world['id']))
  File "/home/tfb/FrameworkBenchmarks/installs/pypy/site-packages/SQLAlchemy-0.8.3-py2.7.egg/sqlalchemy/engine/base.py", line 1613, in execute
    connection = self.contextual_connect(close_with_result=True)
  File "/home/tfb/FrameworkBenchmarks/installs/pypy/site-packages/SQLAlchemy-0.8.3-py2.7.egg/sqlalchemy/engine/base.py", line 1661, in contextual_connect
    self.pool.connect(),
  File "/home/tfb/FrameworkBenchmarks/installs/pypy/site-packages/SQLAlchemy-0.8.3-py2.7.egg/sqlalchemy/pool.py", line 272, in connect
    return _ConnectionFairy(self).checkout()
  File "/home/tfb/FrameworkBenchmarks/installs/pypy/site-packages/SQLAlchemy-0.8.3-py2.7.egg/sqlalchemy/pool.py", line 431, in __init__
    rec = self._connection_record = pool._do_get()
  File "/home/tfb/FrameworkBenchmarks/installs/pypy/site-packages/SQLAlchemy-0.8.3-py2.7.egg/sqlalchemy/pool.py", line 780, in _do_get
    (self.size(), self.overflow(), self._timeout))
TimeoutError: QueuePool limit of size 5 overflow 10 reached, connection timed out, timeout 30
ERROR:app:Exception on /raw-updates [GET]
Traceback (most recent call last):
  File "/home/tfb/FrameworkBenchmarks/installs/pypy/site-packages/Flask-0.10.1-py2.7.egg/flask/app.py", line 1817, in wsgi_app
    response = self.full_dispatch_request()
  File "/home/tfb/FrameworkBenchmarks/installs/pypy/site-packages/Flask-0.10.1-py2.7.egg/flask/app.py", line 1477, in full_dispatch_request
    rv = self.handle_user_exception(e)
  File "/home/tfb/FrameworkBenchmarks/installs/pypy/site-packages/Flask-0.10.1-py2.7.egg/flask/app.py", line 1381, in handle_user_exception
    reraise(exc_type, exc_value, tb)
  File "/home/tfb/FrameworkBenchmarks/installs/pypy/site-packages/Flask-0.10.1-py2.7.egg/flask/app.py", line 1475, in full_dispatch_request
    rv = self.dispatch_request()
  File "/home/tfb/FrameworkBenchmarks/installs/pypy/site-packages/Flask-0.10.1-py2.7.egg/flask/app.py", line 1461, in dispatch_request
    return self.view_functions[rule.endpoint](**req.view_args)
  File "/home/tfb/FrameworkBenchmarks/flask/app.py", line 152, in raw_updates
    (randomNumber, world['id']))
  File "/home/tfb/FrameworkBenchmarks/installs/pypy/site-packages/SQLAlchemy-0.8.3-py2.7.egg/sqlalchemy/engine/base.py", line 1613, in execute
    connection = self.contextual_connect(close_with_result=True)
  File "/home/tfb/FrameworkBenchmarks/installs/pypy/site-packages/SQLAlchemy-0.8.3-py2.7.egg/sqlalchemy/engine/base.py", line 1661, in contextual_connect
    self.pool.connect(),
  File "/home/tfb/FrameworkBenchmarks/installs/pypy/site-packages/SQLAlchemy-0.8.3-py2.7.egg/sqlalchemy/pool.py", line 272, in connect
    return _ConnectionFairy(self).checkout()
  File "/home/tfb/FrameworkBenchmarks/installs/pypy/site-packages/SQLAlchemy-0.8.3-py2.7.egg/sqlalchemy/pool.py", line 431, in __init__
    rec = self._connection_record = pool._do_get()
  File "/home/tfb/FrameworkBenchmarks/installs/pypy/site-packages/SQLAlchemy-0.8.3-py2.7.egg/sqlalchemy/pool.py", line 780, in _do_get
    (self.size(), self.overflow(), self._timeout))
TimeoutError: QueuePool limit of size 5 overflow 10 reached, connection timed out, timeout 30
ERROR:tornado.access:500 GET /raw-updates?queries=2 (172.16.98.98) 30023.96ms
ERROR:tornado.access:500 GET /raw-updates?queries=2 (172.16.98.98) 30022.82ms
2014-03-18 14:05:18 [10914] [CRITICAL] WORKER TIMEOUT (pid:10925)
2014-03-18 14:05:18 [10914] [CRITICAL] WORKER TIMEOUT (pid:10927)
2014-03-18 14:05:18 [10914] [CRITICAL] WORKER TIMEOUT (pid:10928)
2014-03-18 14:05:18 [10914] [CRITICAL] WORKER TIMEOUT (pid:10929)
2014-03-18 14:05:18 [10914] [CRITICAL] WORKER TIMEOUT (pid:10930)
2014-03-18 14:05:18 [10914] [CRITICAL] WORKER TIMEOUT (pid:10934)
2014-03-18 14:05:18 [10914] [CRITICAL] WORKER TIMEOUT (pid:10937)
2014-03-18 14:05:18 [10914] [CRITICAL] WORKER TIMEOUT (pid:10938)
2014-03-18 14:05:18 [10914] [CRITICAL] WORKER TIMEOUT (pid:10940)
2014-03-18 14:05:18 [10914] [CRITICAL] WORKER TIMEOUT (pid:10941)
2014-03-18 14:05:18 [10914] [CRITICAL] WORKER TIMEOUT (pid:10942)
2014-03-18 14:05:18 [10914] [CRITICAL] WORKER TIMEOUT (pid:10944)
2014-03-18 14:05:18 [10914] [CRITICAL] WORKER TIMEOUT (pid:10945)
2014-03-18 14:05:18 [10914] [CRITICAL] WORKER TIMEOUT (pid:10947)
2014-03-18 14:05:18 [10914] [CRITICAL] WORKER TIMEOUT (pid:10948)
2014-03-18 14:05:18 [10914] [CRITICAL] WORKER TIMEOUT (pid:10925)
2014-03-18 14:05:18 [10914] [CRITICAL] WORKER TIMEOUT (pid:10927)
2014-03-18 14:05:18 [10914] [CRITICAL] WORKER TIMEOUT (pid:10928)
2014-03-18 14:05:18 [10914] [CRITICAL] WORKER TIMEOUT (pid:10929)
2014-03-18 14:05:18 [10914] [CRITICAL] WORKER TIMEOUT (pid:10930)
2014-03-18 14:05:18 [10914] [CRITICAL] WORKER TIMEOUT (pid:10934)
2014-03-18 14:05:18 [10914] [CRITICAL] WORKER TIMEOUT (pid:10937)
2014-03-18 14:05:18 [10914] [CRITICAL] WORKER TIMEOUT (pid:10938)
2014-03-18 14:05:18 [10914] [CRITICAL] WORKER TIMEOUT (pid:10940)
2014-03-18 14:05:18 [10914] [CRITICAL] WORKER TIMEOUT (pid:10941)
2014-03-18 14:05:18 [10914] [CRITICAL] WORKER TIMEOUT (pid:10942)
2014-03-18 14:05:18 [10914] [CRITICAL] WORKER TIMEOUT (pid:10944)
2014-03-18 14:05:18 [10914] [CRITICAL] WORKER TIMEOUT (pid:10945)
2014-03-18 14:05:18 [10914] [CRITICAL] WORKER TIMEOUT (pid:10947)
2014-03-18 14:05:18 [10914] [CRITICAL] WORKER TIMEOUT (pid:10948)
2014-03-18 14:05:18 [10914] [CRITICAL] WORKER TIMEOUT (pid:10927)
2014-03-18 14:05:18 [10914] [CRITICAL] WORKER TIMEOUT (pid:10928)
2014-03-18 14:05:18 [10914] [CRITICAL] WORKER TIMEOUT (pid:10929)
2014-03-18 14:05:18 [10914] [CRITICAL] WORKER TIMEOUT (pid:10930)
2014-03-18 14:05:18 [10914] [CRITICAL] WORKER TIMEOUT (pid:10934)
2014-03-18 14:05:18 [10914] [CRITICAL] WORKER TIMEOUT (pid:10937)
2014-03-18 14:05:18 [10914] [CRITICAL] WORKER TIMEOUT (pid:10938)
2014-03-18 14:05:18 [10914] [CRITICAL] WORKER TIMEOUT (pid:10940)
2014-03-18 14:05:18 [10914] [CRITICAL] WORKER TIMEOUT (pid:10941)
2014-03-18 14:05:18 [10914] [CRITICAL] WORKER TIMEOUT (pid:10942)
2014-03-18 14:05:18 [10914] [CRITICAL] WORKER TIMEOUT (pid:10944)
2014-03-18 14:05:18 [10914] [CRITICAL] WORKER TIMEOUT (pid:10945)
2014-03-18 14:05:18 [10914] [CRITICAL] WORKER TIMEOUT (pid:10947)
2014-03-18 14:05:18 [10914] [CRITICAL] WORKER TIMEOUT (pid:10948)
2014-03-18 14:05:37 [10914] [CRITICAL] WORKER TIMEOUT (pid:10991)
2014-03-18 14:05:37 [10914] [CRITICAL] WORKER TIMEOUT (pid:10991)
2014-03-18 14:05:38 [10914] [CRITICAL] WORKER TIMEOUT (pid:10992)
2014-03-18 14:05:38 [10914] [CRITICAL] WORKER TIMEOUT (pid:10993)
2014-03-18 14:05:38 [10914] [CRITICAL] WORKER TIMEOUT (pid:10992)
2014-03-18 14:05:38 [10914] [CRITICAL] WORKER TIMEOUT (pid:10993)
ERROR:app:Exception on /raw-updates [GET]
Traceback (most recent call last):
  File "/home/tfb/FrameworkBenchmarks/installs/pypy/site-packages/Flask-0.10.1-py2.7.egg/flask/app.py", line 1817, in wsgi_app
    response = self.full_dispatch_request()
  File "/home/tfb/FrameworkBenchmarks/installs/pypy/site-packages/Flask-0.10.1-py2.7.egg/flask/app.py", line 1477, in full_dispatch_request
    rv = self.handle_user_exception(e)
  File "/home/tfb/FrameworkBenchmarks/installs/pypy/site-packages/Flask-0.10.1-py2.7.egg/flask/app.py", line 1381, in handle_user_exception
    reraise(exc_type, exc_value, tb)
  File "/home/tfb/FrameworkBenchmarks/installs/pypy/site-packages/Flask-0.10.1-py2.7.egg/flask/app.py", line 1475, in full_dispatch_request
    rv = self.dispatch_request()
  File "/home/tfb/FrameworkBenchmarks/installs/pypy/site-packages/Flask-0.10.1-py2.7.egg/flask/app.py", line 1461, in dispatch_request
    return self.view_functions[rule.endpoint](**req.view_args)
  File "/home/tfb/FrameworkBenchmarks/flask/app.py", line 152, in raw_updates
    (randomNumber, world['id']))
  File "/home/tfb/FrameworkBenchmarks/installs/pypy/site-packages/SQLAlchemy-0.8.3-py2.7.egg/sqlalchemy/engine/base.py", line 1613, in execute
    connection = self.contextual_connect(close_with_result=True)
  File "/home/tfb/FrameworkBenchmarks/installs/pypy/site-packages/SQLAlchemy-0.8.3-py2.7.egg/sqlalchemy/engine/base.py", line 1661, in contextual_connect
    self.pool.connect(),
  File "/home/tfb/FrameworkBenchmarks/installs/pypy/site-packages/SQLAlchemy-0.8.3-py2.7.egg/sqlalchemy/pool.py", line 272, in connect
    return _ConnectionFairy(self).checkout()
  File "/home/tfb/FrameworkBenchmarks/installs/pypy/site-packages/SQLAlchemy-0.8.3-py2.7.egg/sqlalchemy/pool.py", line 431, in __init__
    rec = self._connection_record = pool._do_get()
  File "/home/tfb/FrameworkBenchmarks/installs/pypy/site-packages/SQLAlchemy-0.8.3-py2.7.egg/sqlalchemy/pool.py", line 780, in _do_get
    (self.size(), self.overflow(), self._timeout))
TimeoutError: QueuePool limit of size 5 overflow 10 reached, connection timed out, timeout 30
ERROR:app:Exception on /raw-updates [GET]
Traceback (most recent call last):
  File "/home/tfb/FrameworkBenchmarks/installs/pypy/site-packages/Flask-0.10.1-py2.7.egg/flask/app.py", line 1817, in wsgi_app
    response = self.full_dispatch_request()
  File "/home/tfb/FrameworkBenchmarks/installs/pypy/site-packages/Flask-0.10.1-py2.7.egg/flask/app.py", line 1477, in full_dispatch_request
    rv = self.handle_user_exception(e)
  File "/home/tfb/FrameworkBenchmarks/installs/pypy/site-packages/Flask-0.10.1-py2.7.egg/flask/app.py", line 1381, in handle_user_exception
    reraise(exc_type, exc_value, tb)
  File "/home/tfb/FrameworkBenchmarks/installs/pypy/site-packages/Flask-0.10.1-py2.7.egg/flask/app.py", line 1475, in full_dispatch_request
    rv = self.dispatch_request()
  File "/home/tfb/FrameworkBenchmarks/installs/pypy/site-packages/Flask-0.10.1-py2.7.egg/flask/app.py", line 1461, in dispatch_request
    return self.view_functions[rule.endpoint](**req.view_args)
  File "/home/tfb/FrameworkBenchmarks/flask/app.py", line 152, in raw_updates
    (randomNumber, world['id']))
  File "/home/tfb/FrameworkBenchmarks/installs/pypy/site-packages/SQLAlchemy-0.8.3-py2.7.egg/sqlalchemy/engine/base.py", line 1613, in execute
    connection = self.contextual_connect(close_with_result=True)
  File "/home/tfb/FrameworkBenchmarks/installs/pypy/site-packages/SQLAlchemy-0.8.3-py2.7.egg/sqlalchemy/engine/base.py", line 1661, in contextual_connect
    self.pool.connect(),
  File "/home/tfb/FrameworkBenchmarks/installs/pypy/site-packages/SQLAlchemy-0.8.3-py2.7.egg/sqlalchemy/pool.py", line 272, in connect
    return _ConnectionFairy(self).checkout()
  File "/home/tfb/FrameworkBenchmarks/installs/pypy/site-packages/SQLAlchemy-0.8.3-py2.7.egg/sqlalchemy/pool.py", line 431, in __init__
    rec = self._connection_record = pool._do_get()
  File "/home/tfb/FrameworkBenchmarks/installs/pypy/site-packages/SQLAlchemy-0.8.3-py2.7.egg/sqlalchemy/pool.py", line 780, in _do_get
    (self.size(), self.overflow(), self._timeout))
TimeoutError: QueuePool limit of size 5 overflow 10 reached, connection timed out, timeout 30
ERROR:tornado.access:500 GET /raw-updates?queries=1 (172.16.98.98) 30029.98ms
ERROR:tornado.access:500 GET /raw-updates?queries=1 (172.16.98.98) 30028.97ms
2014-03-18 14:05:39 [10914] [CRITICAL] WORKER TIMEOUT (pid:10994)
2014-03-18 14:05:39 [10914] [CRITICAL] WORKER TIMEOUT (pid:10996)
2014-03-18 14:05:39 [10914] [CRITICAL] WORKER TIMEOUT (pid:10994)
2014-03-18 14:05:39 [10914] [CRITICAL] WORKER TIMEOUT (pid:10996)
ERROR:app:Exception on /raw-updates [GET]
Traceback (most recent call last):
  File "/home/tfb/FrameworkBenchmarks/installs/pypy/site-packages/Flask-0.10.1-py2.7.egg/flask/app.py", line 1817, in wsgi_app
    response = self.full_dispatch_request()
  File "/home/tfb/FrameworkBenchmarks/installs/pypy/site-packages/Flask-0.10.1-py2.7.egg/flask/app.py", line 1477, in full_dispatch_request
    rv = self.handle_user_exception(e)
  File "/home/tfb/FrameworkBenchmarks/installs/pypy/site-packages/Flask-0.10.1-py2.7.egg/flask/app.py", line 1381, in handle_user_exception
    reraise(exc_type, exc_value, tb)
  File "/home/tfb/FrameworkBenchmarks/installs/pypy/site-packages/Flask-0.10.1-py2.7.egg/flask/app.py", line 1475, in full_dispatch_request
    rv = self.dispatch_request()
  File "/home/tfb/FrameworkBenchmarks/installs/pypy/site-packages/Flask-0.10.1-py2.7.egg/flask/app.py", line 1461, in dispatch_request
    return self.view_functions[rule.endpoint](**req.view_args)
  File "/home/tfb/FrameworkBenchmarks/flask/app.py", line 148, in raw_updates
    world = dbraw_engine.execute("SELECT * FROM World WHERE id=%s", (rp(),)).fetchone()
  File "/home/tfb/FrameworkBenchmarks/installs/pypy/site-packages/SQLAlchemy-0.8.3-py2.7.egg/sqlalchemy/engine/base.py", line 1613, in execute
    connection = self.contextual_connect(close_with_result=True)
  File "/home/tfb/FrameworkBenchmarks/installs/pypy/site-packages/SQLAlchemy-0.8.3-py2.7.egg/sqlalchemy/engine/base.py", line 1661, in contextual_connect
    self.pool.connect(),
  File "/home/tfb/FrameworkBenchmarks/installs/pypy/site-packages/SQLAlchemy-0.8.3-py2.7.egg/sqlalchemy/pool.py", line 272, in connect
    return _ConnectionFairy(self).checkout()
  File "/home/tfb/FrameworkBenchmarks/installs/pypy/site-packages/SQLAlchemy-0.8.3-py2.7.egg/sqlalchemy/pool.py", line 431, in __init__
    rec = self._connection_record = pool._do_get()
  File "/home/tfb/FrameworkBenchmarks/installs/pypy/site-packages/SQLAlchemy-0.8.3-py2.7.egg/sqlalchemy/pool.py", line 780, in _do_get
    (self.size(), self.overflow(), self._timeout))
TimeoutError: QueuePool limit of size 5 overflow 10 reached, connection timed out, timeout 30
ERROR:app:Exception on /raw-updates [GET]
Traceback (most recent call last):
  File "/home/tfb/FrameworkBenchmarks/installs/pypy/site-packages/Flask-0.10.1-py2.7.egg/flask/app.py", line 1817, in wsgi_app
    response = self.full_dispatch_request()
  File "/home/tfb/FrameworkBenchmarks/installs/pypy/site-packages/Flask-0.10.1-py2.7.egg/flask/app.py", line 1477, in full_dispatch_request
    rv = self.handle_user_exception(e)
  File "/home/tfb/FrameworkBenchmarks/installs/pypy/site-packages/Flask-0.10.1-py2.7.egg/flask/app.py", line 1381, in handle_user_exception
    reraise(exc_type, exc_value, tb)
  File "/home/tfb/FrameworkBenchmarks/installs/pypy/site-packages/Flask-0.10.1-py2.7.egg/flask/app.py", line 1475, in full_dispatch_request
    rv = self.dispatch_request()
  File "/home/tfb/FrameworkBenchmarks/installs/pypy/site-packages/Flask-0.10.1-py2.7.egg/flask/app.py", line 1461, in dispatch_request
    return self.view_functions[rule.endpoint](**req.view_args)
  File "/home/tfb/FrameworkBenchmarks/flask/app.py", line 148, in raw_updates
    world = dbraw_engine.execute("SELECT * FROM World WHERE id=%s", (rp(),)).fetchone()
  File "/home/tfb/FrameworkBenchmarks/installs/pypy/site-packages/SQLAlchemy-0.8.3-py2.7.egg/sqlalchemy/engine/base.py", line 1613, in execute
    connection = self.contextual_connect(close_with_result=True)
  File "/home/tfb/FrameworkBenchmarks/installs/pypy/site-packages/SQLAlchemy-0.8.3-py2.7.egg/sqlalchemy/engine/base.py", line 1661, in contextual_connect
    self.pool.connect(),
  File "/home/tfb/FrameworkBenchmarks/installs/pypy/site-packages/SQLAlchemy-0.8.3-py2.7.egg/sqlalchemy/pool.py", line 272, in connect
    return _ConnectionFairy(self).checkout()
  File "/home/tfb/FrameworkBenchmarks/installs/pypy/site-packages/SQLAlchemy-0.8.3-py2.7.egg/sqlalchemy/pool.py", line 431, in __init__
    rec = self._connection_record = pool._do_get()
  File "/home/tfb/FrameworkBenchmarks/installs/pypy/site-packages/SQLAlchemy-0.8.3-py2.7.egg/sqlalchemy/pool.py", line 780, in _do_get
    (self.size(), self.overflow(), self._timeout))
TimeoutError: QueuePool limit of size 5 overflow 10 reached, connection timed out, timeout 30
ERROR:tornado.access:500 GET /raw-updates?queries=1 (172.16.98.98) 30003.97ms
ERROR:tornado.access:500 GET /raw-updates?queries=2 (172.16.98.98) 30004.25ms
2014-03-18 14:05:48 [10914] [CRITICAL] WORKER TIMEOUT (pid:10931)
2014-03-18 14:05:48 [10914] [CRITICAL] WORKER TIMEOUT (pid:10936)
2014-03-18 14:05:48 [10914] [CRITICAL] WORKER TIMEOUT (pid:10939)
2014-03-18 14:05:48 [10914] [CRITICAL] WORKER TIMEOUT (pid:10946)
2014-03-18 14:05:48 [10914] [CRITICAL] WORKER TIMEOUT (pid:10931)
2014-03-18 14:05:48 [10914] [CRITICAL] WORKER TIMEOUT (pid:10936)
2014-03-18 14:05:48 [10914] [CRITICAL] WORKER TIMEOUT (pid:10939)
2014-03-18 14:05:48 [10914] [CRITICAL] WORKER TIMEOUT (pid:10946)
2014-03-18 14:05:48 [10914] [CRITICAL] WORKER TIMEOUT (pid:10931)
2014-03-18 14:05:48 [10914] [CRITICAL] WORKER TIMEOUT (pid:10936)
2014-03-18 14:05:56 [10914] [CRITICAL] WORKER TIMEOUT (pid:11005)
2014-03-18 14:05:56 [10914] [CRITICAL] WORKER TIMEOUT (pid:11005)
2014-03-18 14:05:57 [10914] [CRITICAL] WORKER TIMEOUT (pid:11008)
2014-03-18 14:05:57 [10914] [CRITICAL] WORKER TIMEOUT (pid:11009)
2014-03-18 14:05:57 [10914] [CRITICAL] WORKER TIMEOUT (pid:11010)
2014-03-18 14:05:57 [10914] [CRITICAL] WORKER TIMEOUT (pid:11011)
2014-03-18 14:05:57 [10914] [CRITICAL] WORKER TIMEOUT (pid:11012)
2014-03-18 14:05:57 [10914] [CRITICAL] WORKER TIMEOUT (pid:11013)
2014-03-18 14:05:57 [10914] [CRITICAL] WORKER TIMEOUT (pid:11014)
2014-03-18 14:05:57 [10914] [CRITICAL] WORKER TIMEOUT (pid:11015)
2014-03-18 14:05:57 [10914] [CRITICAL] WORKER TIMEOUT (pid:11001)
2014-03-18 14:05:57 [10914] [CRITICAL] WORKER TIMEOUT (pid:11002)
2014-03-18 14:05:57 [10914] [CRITICAL] WORKER TIMEOUT (pid:11003)
2014-03-18 14:05:57 [10914] [CRITICAL] WORKER TIMEOUT (pid:11004)
2014-03-18 14:05:57 [10914] [CRITICAL] WORKER TIMEOUT (pid:11006)
2014-03-18 14:05:57 [10914] [CRITICAL] WORKER TIMEOUT (pid:11007)
2014-03-18 14:05:57 [10914] [CRITICAL] WORKER TIMEOUT (pid:11008)
2014-03-18 14:05:57 [10914] [CRITICAL] WORKER TIMEOUT (pid:11009)
2014-03-18 14:05:57 [10914] [CRITICAL] WORKER TIMEOUT (pid:11010)
2014-03-18 14:05:57 [10914] [CRITICAL] WORKER TIMEOUT (pid:11011)
2014-03-18 14:05:57 [10914] [CRITICAL] WORKER TIMEOUT (pid:11012)
2014-03-18 14:05:57 [10914] [CRITICAL] WORKER TIMEOUT (pid:11013)
2014-03-18 14:05:57 [10914] [CRITICAL] WORKER TIMEOUT (pid:11014)
2014-03-18 14:05:57 [10914] [CRITICAL] WORKER TIMEOUT (pid:11015)
2014-03-18 14:05:57 [10914] [CRITICAL] WORKER TIMEOUT (pid:11001)
2014-03-18 14:05:57 [10914] [CRITICAL] WORKER TIMEOUT (pid:11002)
2014-03-18 14:05:57 [10914] [CRITICAL] WORKER TIMEOUT (pid:11003)
2014-03-18 14:05:57 [10914] [CRITICAL] WORKER TIMEOUT (pid:11004)
2014-03-18 14:05:57 [10914] [CRITICAL] WORKER TIMEOUT (pid:11006)
2014-03-18 14:05:57 [10914] [CRITICAL] WORKER TIMEOUT (pid:11007)
2014-03-18 14:05:57 [10914] [CRITICAL] WORKER TIMEOUT (pid:11008)
2014-03-18 14:05:57 [10914] [CRITICAL] WORKER TIMEOUT (pid:11010)
2014-03-18 14:05:57 [10914] [CRITICAL] WORKER TIMEOUT (pid:11011)
2014-03-18 14:05:57 [10914] [CRITICAL] WORKER TIMEOUT (pid:11012)
2014-03-18 14:05:57 [10914] [CRITICAL] WORKER TIMEOUT (pid:11013)
2014-03-18 14:05:57 [10914] [CRITICAL] WORKER TIMEOUT (pid:11014)
2014-03-18 14:05:57 [10914] [CRITICAL] WORKER TIMEOUT (pid:11015)
2014-03-18 14:05:57 [10914] [CRITICAL] WORKER TIMEOUT (pid:11001)
2014-03-18 14:05:57 [10914] [CRITICAL] WORKER TIMEOUT (pid:11002)
2014-03-18 14:05:57 [10914] [CRITICAL] WORKER TIMEOUT (pid:11003)
2014-03-18 14:05:57 [10914] [CRITICAL] WORKER TIMEOUT (pid:11004)
2014-03-18 14:05:57 [10914] [CRITICAL] WORKER TIMEOUT (pid:11006)
2014-03-18 14:05:57 [10914] [CRITICAL] WORKER TIMEOUT (pid:11007)
ERROR:app:Exception on /raw-updates [GET]
Traceback (most recent call last):
  File "/home/tfb/FrameworkBenchmarks/installs/pypy/site-packages/Flask-0.10.1-py2.7.egg/flask/app.py", line 1817, in wsgi_app
    response = self.full_dispatch_request()
  File "/home/tfb/FrameworkBenchmarks/installs/pypy/site-packages/Flask-0.10.1-py2.7.egg/flask/app.py", line 1477, in full_dispatch_request
    rv = self.handle_user_exception(e)
  File "/home/tfb/FrameworkBenchmarks/installs/pypy/site-packages/Flask-0.10.1-py2.7.egg/flask/app.py", line 1381, in handle_user_exception
    reraise(exc_type, exc_value, tb)
  File "/home/tfb/FrameworkBenchmarks/installs/pypy/site-packages/Flask-0.10.1-py2.7.egg/flask/app.py", line 1475, in full_dispatch_request
    rv = self.dispatch_request()
  File "/home/tfb/FrameworkBenchmarks/installs/pypy/site-packages/Flask-0.10.1-py2.7.egg/flask/app.py", line 1461, in dispatch_request
    return self.view_functions[rule.endpoint](**req.view_args)
  File "/home/tfb/FrameworkBenchmarks/flask/app.py", line 152, in raw_updates
    (randomNumber, world['id']))
  File "/home/tfb/FrameworkBenchmarks/installs/pypy/site-packages/SQLAlchemy-0.8.3-py2.7.egg/sqlalchemy/engine/base.py", line 1613, in execute
    connection = self.contextual_connect(close_with_result=True)
  File "/home/tfb/FrameworkBenchmarks/installs/pypy/site-packages/SQLAlchemy-0.8.3-py2.7.egg/sqlalchemy/engine/base.py", line 1661, in contextual_connect
    self.pool.connect(),
  File "/home/tfb/FrameworkBenchmarks/installs/pypy/site-packages/SQLAlchemy-0.8.3-py2.7.egg/sqlalchemy/pool.py", line 272, in connect
    return _ConnectionFairy(self).checkout()
  File "/home/tfb/FrameworkBenchmarks/installs/pypy/site-packages/SQLAlchemy-0.8.3-py2.7.egg/sqlalchemy/pool.py", line 431, in __init__
    rec = self._connection_record = pool._do_get()
  File "/home/tfb/FrameworkBenchmarks/installs/pypy/site-packages/SQLAlchemy-0.8.3-py2.7.egg/sqlalchemy/pool.py", line 780, in _do_get
    (self.size(), self.overflow(), self._timeout))
TimeoutError: QueuePool limit of size 5 overflow 10 reached, connection timed out, timeout 30
ERROR:tornado.access:500 GET /raw-updates?queries=5 (172.16.98.98) 30039.95ms
2014-03-18 14:06:08 [10914] [CRITICAL] WORKER TIMEOUT (pid:11031)
2014-03-18 14:06:08 [10914] [CRITICAL] WORKER TIMEOUT (pid:11031)
2014-03-18 14:06:15 [10914] [CRITICAL] WORKER TIMEOUT (pid:11033)
2014-03-18 14:06:15 [10914] [CRITICAL] WORKER TIMEOUT (pid:11034)
2014-03-18 14:06:15 [10914] [CRITICAL] WORKER TIMEOUT (pid:11035)
2014-03-18 14:06:15 [10914] [CRITICAL] WORKER TIMEOUT (pid:11036)
2014-03-18 14:06:15 [10914] [CRITICAL] WORKER TIMEOUT (pid:11033)
2014-03-18 14:06:15 [10914] [CRITICAL] WORKER TIMEOUT (pid:11034)
2014-03-18 14:06:15 [10914] [CRITICAL] WORKER TIMEOUT (pid:11035)
2014-03-18 14:06:15 [10914] [CRITICAL] WORKER TIMEOUT (pid:11036)
2014-03-18 14:06:15 [10914] [CRITICAL] WORKER TIMEOUT (pid:11034)
2014-03-18 14:06:15 [10914] [CRITICAL] WORKER TIMEOUT (pid:11036)
ERROR:app:Exception on /raw-updates [GET]
Traceback (most recent call last):
  File "/home/tfb/FrameworkBenchmarks/installs/pypy/site-packages/Flask-0.10.1-py2.7.egg/flask/app.py", line 1817, in wsgi_app
    response = self.full_dispatch_request()
  File "/home/tfb/FrameworkBenchmarks/installs/pypy/site-packages/Flask-0.10.1-py2.7.egg/flask/app.py", line 1477, in full_dispatch_request
    rv = self.handle_user_exception(e)
  File "/home/tfb/FrameworkBenchmarks/installs/pypy/site-packages/Flask-0.10.1-py2.7.egg/flask/app.py", line 1381, in handle_user_exception
    reraise(exc_type, exc_value, tb)
  File "/home/tfb/FrameworkBenchmarks/installs/pypy/site-packages/Flask-0.10.1-py2.7.egg/flask/app.py", line 1475, in full_dispatch_request
    rv = self.dispatch_request()
  File "/home/tfb/FrameworkBenchmarks/installs/pypy/site-packages/Flask-0.10.1-py2.7.egg/flask/app.py", line 1461, in dispatch_request
    return self.view_functions[rule.endpoint](**req.view_args)
  File "/home/tfb/FrameworkBenchmarks/flask/app.py", line 152, in raw_updates
    (randomNumber, world['id']))
  File "/home/tfb/FrameworkBenchmarks/installs/pypy/site-packages/SQLAlchemy-0.8.3-py2.7.egg/sqlalchemy/engine/base.py", line 1613, in execute
    connection = self.contextual_connect(close_with_result=True)
  File "/home/tfb/FrameworkBenchmarks/installs/pypy/site-packages/SQLAlchemy-0.8.3-py2.7.egg/sqlalchemy/engine/base.py", line 1661, in contextual_connect
    self.pool.connect(),
  File "/home/tfb/FrameworkBenchmarks/installs/pypy/site-packages/SQLAlchemy-0.8.3-py2.7.egg/sqlalchemy/pool.py", line 272, in connect
    return _ConnectionFairy(self).checkout()
  File "/home/tfb/FrameworkBenchmarks/installs/pypy/site-packages/SQLAlchemy-0.8.3-py2.7.egg/sqlalchemy/pool.py", line 431, in __init__
    rec = self._connection_record = pool._do_get()
  File "/home/tfb/FrameworkBenchmarks/installs/pypy/site-packages/SQLAlchemy-0.8.3-py2.7.egg/sqlalchemy/pool.py", line 780, in _do_get
    (self.size(), self.overflow(), self._timeout))
TimeoutError: QueuePool limit of size 5 overflow 10 reached, connection timed out, timeout 30
ERROR:tornado.access:500 GET /raw-updates?queries=10 (172.16.98.98) 30038.59ms
2014-03-18 14:06:19 [10914] [CRITICAL] WORKER TIMEOUT (pid:11041)
2014-03-18 14:06:19 [10914] [CRITICAL] WORKER TIMEOUT (pid:11041)
2014-03-18 14:06:32 [10914] [CRITICAL] WORKER TIMEOUT (pid:11042)
2014-03-18 14:06:32 [10914] [CRITICAL] WORKER TIMEOUT (pid:11043)
2014-03-18 14:06:32 [10914] [CRITICAL] WORKER TIMEOUT (pid:11044)
2014-03-18 14:06:32 [10914] [CRITICAL] WORKER TIMEOUT (pid:11046)
2014-03-18 14:06:32 [10914] [CRITICAL] WORKER TIMEOUT (pid:11047)
2014-03-18 14:06:32 [10914] [CRITICAL] WORKER TIMEOUT (pid:11042)
2014-03-18 14:06:32 [10914] [CRITICAL] WORKER TIMEOUT (pid:11043)
2014-03-18 14:06:32 [10914] [CRITICAL] WORKER TIMEOUT (pid:11044)
2014-03-18 14:06:32 [10914] [CRITICAL] WORKER TIMEOUT (pid:11046)
2014-03-18 14:06:32 [10914] [CRITICAL] WORKER TIMEOUT (pid:11047)
2014-03-18 14:06:32 [10914] [CRITICAL] WORKER TIMEOUT (pid:11047)
ERROR:app:Exception on /raw-updates [GET]
Traceback (most recent call last):
  File "/home/tfb/FrameworkBenchmarks/installs/pypy/site-packages/Flask-0.10.1-py2.7.egg/flask/app.py", line 1817, in wsgi_app
    response = self.full_dispatch_request()
  File "/home/tfb/FrameworkBenchmarks/installs/pypy/site-packages/Flask-0.10.1-py2.7.egg/flask/app.py", line 1477, in full_dispatch_request
    rv = self.handle_user_exception(e)
  File "/home/tfb/FrameworkBenchmarks/installs/pypy/site-packages/Flask-0.10.1-py2.7.egg/flask/app.py", line 1381, in handle_user_exception
    reraise(exc_type, exc_value, tb)
  File "/home/tfb/FrameworkBenchmarks/installs/pypy/site-packages/Flask-0.10.1-py2.7.egg/flask/app.py", line 1475, in full_dispatch_request
    rv = self.dispatch_request()
  File "/home/tfb/FrameworkBenchmarks/installs/pypy/site-packages/Flask-0.10.1-py2.7.egg/flask/app.py", line 1461, in dispatch_request
    return self.view_functions[rule.endpoint](**req.view_args)
  File "/home/tfb/FrameworkBenchmarks/flask/app.py", line 152, in raw_updates
    (randomNumber, world['id']))
  File "/home/tfb/FrameworkBenchmarks/installs/pypy/site-packages/SQLAlchemy-0.8.3-py2.7.egg/sqlalchemy/engine/base.py", line 1613, in execute
    connection = self.contextual_connect(close_with_result=True)
  File "/home/tfb/FrameworkBenchmarks/installs/pypy/site-packages/SQLAlchemy-0.8.3-py2.7.egg/sqlalchemy/engine/base.py", line 1661, in contextual_connect
    self.pool.connect(),
  File "/home/tfb/FrameworkBenchmarks/installs/pypy/site-packages/SQLAlchemy-0.8.3-py2.7.egg/sqlalchemy/pool.py", line 272, in connect
    return _ConnectionFairy(self).checkout()
  File "/home/tfb/FrameworkBenchmarks/installs/pypy/site-packages/SQLAlchemy-0.8.3-py2.7.egg/sqlalchemy/pool.py", line 431, in __init__
    rec = self._connection_record = pool._do_get()
  File "/home/tfb/FrameworkBenchmarks/installs/pypy/site-packages/SQLAlchemy-0.8.3-py2.7.egg/sqlalchemy/pool.py", line 780, in _do_get
    (self.size(), self.overflow(), self._timeout))
TimeoutError: QueuePool limit of size 5 overflow 10 reached, connection timed out, timeout 30
ERROR:app:Exception on /raw-updates [GET]
Traceback (most recent call last):
  File "/home/tfb/FrameworkBenchmarks/installs/pypy/site-packages/Flask-0.10.1-py2.7.egg/flask/app.py", line 1817, in wsgi_app
    response = self.full_dispatch_request()
  File "/home/tfb/FrameworkBenchmarks/installs/pypy/site-packages/Flask-0.10.1-py2.7.egg/flask/app.py", line 1477, in full_dispatch_request
    rv = self.handle_user_exception(e)
  File "/home/tfb/FrameworkBenchmarks/installs/pypy/site-packages/Flask-0.10.1-py2.7.egg/flask/app.py", line 1381, in handle_user_exception
    reraise(exc_type, exc_value, tb)
  File "/home/tfb/FrameworkBenchmarks/installs/pypy/site-packages/Flask-0.10.1-py2.7.egg/flask/app.py", line 1475, in full_dispatch_request
    rv = self.dispatch_request()
  File "/home/tfb/FrameworkBenchmarks/installs/pypy/site-packages/Flask-0.10.1-py2.7.egg/flask/app.py", line 1461, in dispatch_request
    return self.view_functions[rule.endpoint](**req.view_args)
  File "/home/tfb/FrameworkBenchmarks/flask/app.py", line 152, in raw_updates
    (randomNumber, world['id']))
  File "/home/tfb/FrameworkBenchmarks/installs/pypy/site-packages/SQLAlchemy-0.8.3-py2.7.egg/sqlalchemy/engine/base.py", line 1613, in execute
    connection = self.contextual_connect(close_with_result=True)
  File "/home/tfb/FrameworkBenchmarks/installs/pypy/site-packages/SQLAlchemy-0.8.3-py2.7.egg/sqlalchemy/engine/base.py", line 1661, in contextual_connect
    self.pool.connect(),
  File "/home/tfb/FrameworkBenchmarks/installs/pypy/site-packages/SQLAlchemy-0.8.3-py2.7.egg/sqlalchemy/pool.py", line 272, in connect
    return _ConnectionFairy(self).checkout()
  File "/home/tfb/FrameworkBenchmarks/installs/pypy/site-packages/SQLAlchemy-0.8.3-py2.7.egg/sqlalchemy/pool.py", line 431, in __init__
    rec = self._connection_record = pool._do_get()
  File "/home/tfb/FrameworkBenchmarks/installs/pypy/site-packages/SQLAlchemy-0.8.3-py2.7.egg/sqlalchemy/pool.py", line 780, in _do_get
    (self.size(), self.overflow(), self._timeout))
TimeoutError: QueuePool limit of size 5 overflow 10 reached, connection timed out, timeout 30
ERROR:app:Exception on /raw-updates [GET]
Traceback (most recent call last):
  File "/home/tfb/FrameworkBenchmarks/installs/pypy/site-packages/Flask-0.10.1-py2.7.egg/flask/app.py", line 1817, in wsgi_app
    response = self.full_dispatch_request()
  File "/home/tfb/FrameworkBenchmarks/installs/pypy/site-packages/Flask-0.10.1-py2.7.egg/flask/app.py", line 1477, in full_dispatch_request
    rv = self.handle_user_exception(e)
  File "/home/tfb/FrameworkBenchmarks/installs/pypy/site-packages/Flask-0.10.1-py2.7.egg/flask/app.py", line 1381, in handle_user_exception
    reraise(exc_type, exc_value, tb)
  File "/home/tfb/FrameworkBenchmarks/installs/pypy/site-packages/Flask-0.10.1-py2.7.egg/flask/app.py", line 1475, in full_dispatch_request
    rv = self.dispatch_request()
  File "/home/tfb/FrameworkBenchmarks/installs/pypy/site-packages/Flask-0.10.1-py2.7.egg/flask/app.py", line 1461, in dispatch_request
    return self.view_functions[rule.endpoint](**req.view_args)
  File "/home/tfb/FrameworkBenchmarks/flask/app.py", line 152, in raw_updates
    (randomNumber, world['id']))
  File "/home/tfb/FrameworkBenchmarks/installs/pypy/site-packages/SQLAlchemy-0.8.3-py2.7.egg/sqlalchemy/engine/base.py", line 1613, in execute
    connection = self.contextual_connect(close_with_result=True)
  File "/home/tfb/FrameworkBenchmarks/installs/pypy/site-packages/SQLAlchemy-0.8.3-py2.7.egg/sqlalchemy/engine/base.py", line 1661, in contextual_connect
    self.pool.connect(),
  File "/home/tfb/FrameworkBenchmarks/installs/pypy/site-packages/SQLAlchemy-0.8.3-py2.7.egg/sqlalchemy/pool.py", line 272, in connect
    return _ConnectionFairy(self).checkout()
  File "/home/tfb/FrameworkBenchmarks/installs/pypy/site-packages/SQLAlchemy-0.8.3-py2.7.egg/sqlalchemy/pool.py", line 431, in __init__
    rec = self._connection_record = pool._do_get()
  File "/home/tfb/FrameworkBenchmarks/installs/pypy/site-packages/SQLAlchemy-0.8.3-py2.7.egg/sqlalchemy/pool.py", line 780, in _do_get
    (self.size(), self.overflow(), self._timeout))
TimeoutError: QueuePool limit of size 5 overflow 10 reached, connection timed out, timeout 30
ERROR:app:Exception on /raw-updates [GET]
Traceback (most recent call last):
  File "/home/tfb/FrameworkBenchmarks/installs/pypy/site-packages/Flask-0.10.1-py2.7.egg/flask/app.py", line 1817, in wsgi_app
    response = self.full_dispatch_request()
  File "/home/tfb/FrameworkBenchmarks/installs/pypy/site-packages/Flask-0.10.1-py2.7.egg/flask/app.py", line 1477, in full_dispatch_request
    rv = self.handle_user_exception(e)
  File "/home/tfb/FrameworkBenchmarks/installs/pypy/site-packages/Flask-0.10.1-py2.7.egg/flask/app.py", line 1381, in handle_user_exception
    reraise(exc_type, exc_value, tb)
  File "/home/tfb/FrameworkBenchmarks/installs/pypy/site-packages/Flask-0.10.1-py2.7.egg/flask/app.py", line 1475, in full_dispatch_request
    rv = self.dispatch_request()
  File "/home/tfb/FrameworkBenchmarks/installs/pypy/site-packages/Flask-0.10.1-py2.7.egg/flask/app.py", line 1461, in dispatch_request
    return self.view_functions[rule.endpoint](**req.view_args)
  File "/home/tfb/FrameworkBenchmarks/flask/app.py", line 152, in raw_updates
    (randomNumber, world['id']))
  File "/home/tfb/FrameworkBenchmarks/installs/pypy/site-packages/SQLAlchemy-0.8.3-py2.7.egg/sqlalchemy/engine/base.py", line 1613, in execute
    connection = self.contextual_connect(close_with_result=True)
  File "/home/tfb/FrameworkBenchmarks/installs/pypy/site-packages/SQLAlchemy-0.8.3-py2.7.egg/sqlalchemy/engine/base.py", line 1661, in contextual_connect
    self.pool.connect(),
  File "/home/tfb/FrameworkBenchmarks/installs/pypy/site-packages/SQLAlchemy-0.8.3-py2.7.egg/sqlalchemy/pool.py", line 272, in connect
    return _ConnectionFairy(self).checkout()
  File "/home/tfb/FrameworkBenchmarks/installs/pypy/site-packages/SQLAlchemy-0.8.3-py2.7.egg/sqlalchemy/pool.py", line 431, in __init__
    rec = self._connection_record = pool._do_get()
  File "/home/tfb/FrameworkBenchmarks/installs/pypy/site-packages/SQLAlchemy-0.8.3-py2.7.egg/sqlalchemy/pool.py", line 780, in _do_get
    (self.size(), self.overflow(), self._timeout))
TimeoutError: QueuePool limit of size 5 overflow 10 reached, connection timed out, timeout 30
ERROR:app:Exception on /raw-updates [GET]
Traceback (most recent call last):
  File "/home/tfb/FrameworkBenchmarks/installs/pypy/site-packages/Flask-0.10.1-py2.7.egg/flask/app.py", line 1817, in wsgi_app
    response = self.full_dispatch_request()
  File "/home/tfb/FrameworkBenchmarks/installs/pypy/site-packages/Flask-0.10.1-py2.7.egg/flask/app.py", line 1477, in full_dispatch_request
    rv = self.handle_user_exception(e)
  File "/home/tfb/FrameworkBenchmarks/installs/pypy/site-packages/Flask-0.10.1-py2.7.egg/flask/app.py", line 1381, in handle_user_exception
    reraise(exc_type, exc_value, tb)
  File "/home/tfb/FrameworkBenchmarks/installs/pypy/site-packages/Flask-0.10.1-py2.7.egg/flask/app.py", line 1475, in full_dispatch_request
    rv = self.dispatch_request()
  File "/home/tfb/FrameworkBenchmarks/installs/pypy/site-packages/Flask-0.10.1-py2.7.egg/flask/app.py", line 1461, in dispatch_request
    return self.view_functions[rule.endpoint](**req.view_args)
  File "/home/tfb/FrameworkBenchmarks/flask/app.py", line 152, in raw_updates
    (randomNumber, world['id']))
  File "/home/tfb/FrameworkBenchmarks/installs/pypy/site-packages/SQLAlchemy-0.8.3-py2.7.egg/sqlalchemy/engine/base.py", line 1613, in execute
    connection = self.contextual_connect(close_with_result=True)
  File "/home/tfb/FrameworkBenchmarks/installs/pypy/site-packages/SQLAlchemy-0.8.3-py2.7.egg/sqlalchemy/engine/base.py", line 1661, in contextual_connect
    self.pool.connect(),
  File "/home/tfb/FrameworkBenchmarks/installs/pypy/site-packages/SQLAlchemy-0.8.3-py2.7.egg/sqlalchemy/pool.py", line 272, in connect
    return _ConnectionFairy(self).checkout()
  File "/home/tfb/FrameworkBenchmarks/installs/pypy/site-packages/SQLAlchemy-0.8.3-py2.7.egg/sqlalchemy/pool.py", line 431, in __init__
    rec = self._connection_record = pool._do_get()
  File "/home/tfb/FrameworkBenchmarks/installs/pypy/site-packages/SQLAlchemy-0.8.3-py2.7.egg/sqlalchemy/pool.py", line 780, in _do_get
    (self.size(), self.overflow(), self._timeout))
TimeoutError: QueuePool limit of size 5 overflow 10 reached, connection timed out, timeout 30
ERROR:app:Exception on /raw-updates [GET]
Traceback (most recent call last):
  File "/home/tfb/FrameworkBenchmarks/installs/pypy/site-packages/Flask-0.10.1-py2.7.egg/flask/app.py", line 1817, in wsgi_app
    response = self.full_dispatch_request()
  File "/home/tfb/FrameworkBenchmarks/installs/pypy/site-packages/Flask-0.10.1-py2.7.egg/flask/app.py", line 1477, in full_dispatch_request
    rv = self.handle_user_exception(e)
  File "/home/tfb/FrameworkBenchmarks/installs/pypy/site-packages/Flask-0.10.1-py2.7.egg/flask/app.py", line 1381, in handle_user_exception
    reraise(exc_type, exc_value, tb)
  File "/home/tfb/FrameworkBenchmarks/installs/pypy/site-packages/Flask-0.10.1-py2.7.egg/flask/app.py", line 1475, in full_dispatch_request
    rv = self.dispatch_request()
  File "/home/tfb/FrameworkBenchmarks/installs/pypy/site-packages/Flask-0.10.1-py2.7.egg/flask/app.py", line 1461, in dispatch_request
    return self.view_functions[rule.endpoint](**req.view_args)
  File "/home/tfb/FrameworkBenchmarks/flask/app.py", line 152, in raw_updates
    (randomNumber, world['id']))
  File "/home/tfb/FrameworkBenchmarks/installs/pypy/site-packages/SQLAlchemy-0.8.3-py2.7.egg/sqlalchemy/engine/base.py", line 1613, in execute
    connection = self.contextual_connect(close_with_result=True)
  File "/home/tfb/FrameworkBenchmarks/installs/pypy/site-packages/SQLAlchemy-0.8.3-py2.7.egg/sqlalchemy/engine/base.py", line 1661, in contextual_connect
    self.pool.connect(),
  File "/home/tfb/FrameworkBenchmarks/installs/pypy/site-packages/SQLAlchemy-0.8.3-py2.7.egg/sqlalchemy/pool.py", line 272, in connect
    return _ConnectionFairy(self).checkout()
  File "/home/tfb/FrameworkBenchmarks/installs/pypy/site-packages/SQLAlchemy-0.8.3-py2.7.egg/sqlalchemy/pool.py", line 431, in __init__
    rec = self._connection_record = pool._do_get()
  File "/home/tfb/FrameworkBenchmarks/installs/pypy/site-packages/SQLAlchemy-0.8.3-py2.7.egg/sqlalchemy/pool.py", line 780, in _do_get
    (self.size(), self.overflow(), self._timeout))
TimeoutError: QueuePool limit of size 5 overflow 10 reached, connection timed out, timeout 30
ERROR:app:Exception on /raw-updates [GET]
Traceback (most recent call last):
  File "/home/tfb/FrameworkBenchmarks/installs/pypy/site-packages/Flask-0.10.1-py2.7.egg/flask/app.py", line 1817, in wsgi_app
    response = self.full_dispatch_request()
  File "/home/tfb/FrameworkBenchmarks/installs/pypy/site-packages/Flask-0.10.1-py2.7.egg/flask/app.py", line 1477, in full_dispatch_request
    rv = self.handle_user_exception(e)
  File "/home/tfb/FrameworkBenchmarks/installs/pypy/site-packages/Flask-0.10.1-py2.7.egg/flask/app.py", line 1381, in handle_user_exception
    reraise(exc_type, exc_value, tb)
  File "/home/tfb/FrameworkBenchmarks/installs/pypy/site-packages/Flask-0.10.1-py2.7.egg/flask/app.py", line 1475, in full_dispatch_request
    rv = self.dispatch_request()
  File "/home/tfb/FrameworkBenchmarks/installs/pypy/site-packages/Flask-0.10.1-py2.7.egg/flask/app.py", line 1461, in dispatch_request
    return self.view_functions[rule.endpoint](**req.view_args)
  File "/home/tfb/FrameworkBenchmarks/flask/app.py", line 152, in raw_updates
    (randomNumber, world['id']))
  File "/home/tfb/FrameworkBenchmarks/installs/pypy/site-packages/SQLAlchemy-0.8.3-py2.7.egg/sqlalchemy/engine/base.py", line 1613, in execute
    connection = self.contextual_connect(close_with_result=True)
  File "/home/tfb/FrameworkBenchmarks/installs/pypy/site-packages/SQLAlchemy-0.8.3-py2.7.egg/sqlalchemy/engine/base.py", line 1661, in contextual_connect
    self.pool.connect(),
  File "/home/tfb/FrameworkBenchmarks/installs/pypy/site-packages/SQLAlchemy-0.8.3-py2.7.egg/sqlalchemy/pool.py", line 272, in connect
    return _ConnectionFairy(self).checkout()
  File "/home/tfb/FrameworkBenchmarks/installs/pypy/site-packages/SQLAlchemy-0.8.3-py2.7.egg/sqlalchemy/pool.py", line 431, in __init__
    rec = self._connection_record = pool._do_get()
  File "/home/tfb/FrameworkBenchmarks/installs/pypy/site-packages/SQLAlchemy-0.8.3-py2.7.egg/sqlalchemy/pool.py", line 780, in _do_get
    (self.size(), self.overflow(), self._timeout))
TimeoutError: QueuePool limit of size 5 overflow 10 reached, connection timed out, timeout 30
ERROR:app:Exception on /raw-updates [GET]
Traceback (most recent call last):
  File "/home/tfb/FrameworkBenchmarks/installs/pypy/site-packages/Flask-0.10.1-py2.7.egg/flask/app.py", line 1817, in wsgi_app
    response = self.full_dispatch_request()
  File "/home/tfb/FrameworkBenchmarks/installs/pypy/site-packages/Flask-0.10.1-py2.7.egg/flask/app.py", line 1477, in full_dispatch_request
    rv = self.handle_user_exception(e)
  File "/home/tfb/FrameworkBenchmarks/installs/pypy/site-packages/Flask-0.10.1-py2.7.egg/flask/app.py", line 1381, in handle_user_exception
    reraise(exc_type, exc_value, tb)
  File "/home/tfb/FrameworkBenchmarks/installs/pypy/site-packages/Flask-0.10.1-py2.7.egg/flask/app.py", line 1475, in full_dispatch_request
    rv = self.dispatch_request()
  File "/home/tfb/FrameworkBenchmarks/installs/pypy/site-packages/Flask-0.10.1-py2.7.egg/flask/app.py", line 1461, in dispatch_request
    return self.view_functions[rule.endpoint](**req.view_args)
  File "/home/tfb/FrameworkBenchmarks/flask/app.py", line 152, in raw_updates
    (randomNumber, world['id']))
  File "/home/tfb/FrameworkBenchmarks/installs/pypy/site-packages/SQLAlchemy-0.8.3-py2.7.egg/sqlalchemy/engine/base.py", line 1613, in execute
    connection = self.contextual_connect(close_with_result=True)
  File "/home/tfb/FrameworkBenchmarks/installs/pypy/site-packages/SQLAlchemy-0.8.3-py2.7.egg/sqlalchemy/engine/base.py", line 1661, in contextual_connect
    self.pool.connect(),
  File "/home/tfb/FrameworkBenchmarks/installs/pypy/site-packages/SQLAlchemy-0.8.3-py2.7.egg/sqlalchemy/pool.py", line 272, in connect
    return _ConnectionFairy(self).checkout()
  File "/home/tfb/FrameworkBenchmarks/installs/pypy/site-packages/SQLAlchemy-0.8.3-py2.7.egg/sqlalchemy/pool.py", line 431, in __init__
    rec = self._connection_record = pool._do_get()
  File "/home/tfb/FrameworkBenchmarks/installs/pypy/site-packages/SQLAlchemy-0.8.3-py2.7.egg/sqlalchemy/pool.py", line 780, in _do_get
    (self.size(), self.overflow(), self._timeout))
TimeoutError: QueuePool limit of size 5 overflow 10 reached, connection timed out, timeout 30
ERROR:app:Exception on /raw-updates [GET]
Traceback (most recent call last):
  File "/home/tfb/FrameworkBenchmarks/installs/pypy/site-packages/Flask-0.10.1-py2.7.egg/flask/app.py", line 1817, in wsgi_app
    response = self.full_dispatch_request()
  File "/home/tfb/FrameworkBenchmarks/installs/pypy/site-packages/Flask-0.10.1-py2.7.egg/flask/app.py", line 1477, in full_dispatch_request
    rv = self.handle_user_exception(e)
  File "/home/tfb/FrameworkBenchmarks/installs/pypy/site-packages/Flask-0.10.1-py2.7.egg/flask/app.py", line 1381, in handle_user_exception
    reraise(exc_type, exc_value, tb)
  File "/home/tfb/FrameworkBenchmarks/installs/pypy/site-packages/Flask-0.10.1-py2.7.egg/flask/app.py", line 1475, in full_dispatch_request
    rv = self.dispatch_request()
  File "/home/tfb/FrameworkBenchmarks/installs/pypy/site-packages/Flask-0.10.1-py2.7.egg/flask/app.py", line 1461, in dispatch_request
    return self.view_functions[rule.endpoint](**req.view_args)
  File "/home/tfb/FrameworkBenchmarks/flask/app.py", line 152, in raw_updates
    (randomNumber, world['id']))
  File "/home/tfb/FrameworkBenchmarks/installs/pypy/site-packages/SQLAlchemy-0.8.3-py2.7.egg/sqlalchemy/engine/base.py", line 1613, in execute
    connection = self.contextual_connect(close_with_result=True)
  File "/home/tfb/FrameworkBenchmarks/installs/pypy/site-packages/SQLAlchemy-0.8.3-py2.7.egg/sqlalchemy/engine/base.py", line 1661, in contextual_connect
    self.pool.connect(),
  File "/home/tfb/FrameworkBenchmarks/installs/pypy/site-packages/SQLAlchemy-0.8.3-py2.7.egg/sqlalchemy/pool.py", line 272, in connect
    return _ConnectionFairy(self).checkout()
  File "/home/tfb/FrameworkBenchmarks/installs/pypy/site-packages/SQLAlchemy-0.8.3-py2.7.egg/sqlalchemy/pool.py", line 431, in __init__
    rec = self._connection_record = pool._do_get()
  File "/home/tfb/FrameworkBenchmarks/installs/pypy/site-packages/SQLAlchemy-0.8.3-py2.7.egg/sqlalchemy/pool.py", line 780, in _do_get
    (self.size(), self.overflow(), self._timeout))
TimeoutError: QueuePool limit of size 5 overflow 10 reached, connection timed out, timeout 30
ERROR:tornado.access:500 GET /raw-updates?queries=15 (172.16.98.98) 30123.97ms
ERROR:tornado.access:500 GET /raw-updates?queries=15 (172.16.98.98) 30127.68ms
ERROR:tornado.access:500 GET /raw-updates?queries=15 (172.16.98.98) 30128.40ms
ERROR:tornado.access:500 GET /raw-updates?queries=15 (172.16.98.98) 30126.58ms
ERROR:tornado.access:500 GET /raw-updates?queries=15 (172.16.98.98) 30138.29ms
ERROR:tornado.access:500 GET /raw-updates?queries=15 (172.16.98.98) 30122.06ms
ERROR:tornado.access:500 GET /raw-updates?queries=15 (172.16.98.98) 30138.08ms
ERROR:tornado.access:500 GET /raw-updates?queries=15 (172.16.98.98) 30149.50ms
ERROR:tornado.access:500 GET /raw-updates?queries=15 (172.16.98.98) 30151.12ms
ERROR:app:Exception on /raw-updates [GET]
Traceback (most recent call last):
  File "/home/tfb/FrameworkBenchmarks/installs/pypy/site-packages/Flask-0.10.1-py2.7.egg/flask/app.py", line 1817, in wsgi_app
    response = self.full_dispatch_request()
  File "/home/tfb/FrameworkBenchmarks/installs/pypy/site-packages/Flask-0.10.1-py2.7.egg/flask/app.py", line 1477, in full_dispatch_request
    rv = self.handle_user_exception(e)
  File "/home/tfb/FrameworkBenchmarks/installs/pypy/site-packages/Flask-0.10.1-py2.7.egg/flask/app.py", line 1381, in handle_user_exception
    reraise(exc_type, exc_value, tb)
  File "/home/tfb/FrameworkBenchmarks/installs/pypy/site-packages/Flask-0.10.1-py2.7.egg/flask/app.py", line 1475, in full_dispatch_request
    rv = self.dispatch_request()
  File "/home/tfb/FrameworkBenchmarks/installs/pypy/site-packages/Flask-0.10.1-py2.7.egg/flask/app.py", line 1461, in dispatch_request
    return self.view_functions[rule.endpoint](**req.view_args)
  File "/home/tfb/FrameworkBenchmarks/flask/app.py", line 152, in raw_updates
    (randomNumber, world['id']))
  File "/home/tfb/FrameworkBenchmarks/installs/pypy/site-packages/SQLAlchemy-0.8.3-py2.7.egg/sqlalchemy/engine/base.py", line 1613, in execute
    connection = self.contextual_connect(close_with_result=True)
  File "/home/tfb/FrameworkBenchmarks/installs/pypy/site-packages/SQLAlchemy-0.8.3-py2.7.egg/sqlalchemy/engine/base.py", line 1661, in contextual_connect
    self.pool.connect(),
  File "/home/tfb/FrameworkBenchmarks/installs/pypy/site-packages/SQLAlchemy-0.8.3-py2.7.egg/sqlalchemy/pool.py", line 272, in connect
    return _ConnectionFairy(self).checkout()
  File "/home/tfb/FrameworkBenchmarks/installs/pypy/site-packages/SQLAlchemy-0.8.3-py2.7.egg/sqlalchemy/pool.py", line 431, in __init__
    rec = self._connection_record = pool._do_get()
  File "/home/tfb/FrameworkBenchmarks/installs/pypy/site-packages/SQLAlchemy-0.8.3-py2.7.egg/sqlalchemy/pool.py", line 780, in _do_get
    (self.size(), self.overflow(), self._timeout))
TimeoutError: QueuePool limit of size 5 overflow 10 reached, connection timed out, timeout 30
ERROR:app:Exception on /raw-updates [GET]
Traceback (most recent call last):
  File "/home/tfb/FrameworkBenchmarks/installs/pypy/site-packages/Flask-0.10.1-py2.7.egg/flask/app.py", line 1817, in wsgi_app
    response = self.full_dispatch_request()
  File "/home/tfb/FrameworkBenchmarks/installs/pypy/site-packages/Flask-0.10.1-py2.7.egg/flask/app.py", line 1477, in full_dispatch_request
    rv = self.handle_user_exception(e)
  File "/home/tfb/FrameworkBenchmarks/installs/pypy/site-packages/Flask-0.10.1-py2.7.egg/flask/app.py", line 1381, in handle_user_exception
    reraise(exc_type, exc_value, tb)
  File "/home/tfb/FrameworkBenchmarks/installs/pypy/site-packages/Flask-0.10.1-py2.7.egg/flask/app.py", line 1475, in full_dispatch_request
    rv = self.dispatch_request()
  File "/home/tfb/FrameworkBenchmarks/installs/pypy/site-packages/Flask-0.10.1-py2.7.egg/flask/app.py", line 1461, in dispatch_request
    return self.view_functions[rule.endpoint](**req.view_args)
  File "/home/tfb/FrameworkBenchmarks/flask/app.py", line 152, in raw_updates
    (randomNumber, world['id']))
  File "/home/tfb/FrameworkBenchmarks/installs/pypy/site-packages/SQLAlchemy-0.8.3-py2.7.egg/sqlalchemy/engine/base.py", line 1613, in execute
    connection = self.contextual_connect(close_with_result=True)
  File "/home/tfb/FrameworkBenchmarks/installs/pypy/site-packages/SQLAlchemy-0.8.3-py2.7.egg/sqlalchemy/engine/base.py", line 1661, in contextual_connect
    self.pool.connect(),
  File "/home/tfb/FrameworkBenchmarks/installs/pypy/site-packages/SQLAlchemy-0.8.3-py2.7.egg/sqlalchemy/pool.py", line 272, in connect
    return _ConnectionFairy(self).checkout()
  File "/home/tfb/FrameworkBenchmarks/installs/pypy/site-packages/SQLAlchemy-0.8.3-py2.7.egg/sqlalchemy/pool.py", line 431, in __init__
    rec = self._connection_record = pool._do_get()
  File "/home/tfb/FrameworkBenchmarks/installs/pypy/site-packages/SQLAlchemy-0.8.3-py2.7.egg/sqlalchemy/pool.py", line 780, in _do_get
    (self.size(), self.overflow(), self._timeout))
TimeoutError: QueuePool limit of size 5 overflow 10 reached, connection timed out, timeout 30
ERROR:app:Exception on /raw-updates [GET]
Traceback (most recent call last):
  File "/home/tfb/FrameworkBenchmarks/installs/pypy/site-packages/Flask-0.10.1-py2.7.egg/flask/app.py", line 1817, in wsgi_app
    response = self.full_dispatch_request()
  File "/home/tfb/FrameworkBenchmarks/installs/pypy/site-packages/Flask-0.10.1-py2.7.egg/flask/app.py", line 1477, in full_dispatch_request
    rv = self.handle_user_exception(e)
  File "/home/tfb/FrameworkBenchmarks/installs/pypy/site-packages/Flask-0.10.1-py2.7.egg/flask/app.py", line 1381, in handle_user_exception
    reraise(exc_type, exc_value, tb)
  File "/home/tfb/FrameworkBenchmarks/installs/pypy/site-packages/Flask-0.10.1-py2.7.egg/flask/app.py", line 1475, in full_dispatch_request
    rv = self.dispatch_request()
  File "/home/tfb/FrameworkBenchmarks/installs/pypy/site-packages/Flask-0.10.1-py2.7.egg/flask/app.py", line 1461, in dispatch_request
    return self.view_functions[rule.endpoint](**req.view_args)
  File "/home/tfb/FrameworkBenchmarks/flask/app.py", line 152, in raw_updates
    (randomNumber, world['id']))
  File "/home/tfb/FrameworkBenchmarks/installs/pypy/site-packages/SQLAlchemy-0.8.3-py2.7.egg/sqlalchemy/engine/base.py", line 1613, in execute
    connection = self.contextual_connect(close_with_result=True)
  File "/home/tfb/FrameworkBenchmarks/installs/pypy/site-packages/SQLAlchemy-0.8.3-py2.7.egg/sqlalchemy/engine/base.py", line 1661, in contextual_connect
    self.pool.connect(),
  File "/home/tfb/FrameworkBenchmarks/installs/pypy/site-packages/SQLAlchemy-0.8.3-py2.7.egg/sqlalchemy/pool.py", line 272, in connect
    return _ConnectionFairy(self).checkout()
  File "/home/tfb/FrameworkBenchmarks/installs/pypy/site-packages/SQLAlchemy-0.8.3-py2.7.egg/sqlalchemy/pool.py", line 431, in __init__
    rec = self._connection_record = pool._do_get()
  File "/home/tfb/FrameworkBenchmarks/installs/pypy/site-packages/SQLAlchemy-0.8.3-py2.7.egg/sqlalchemy/pool.py", line 780, in _do_get
    (self.size(), self.overflow(), self._timeout))
TimeoutError: QueuePool limit of size 5 overflow 10 reached, connection timed out, timeout 30
ERROR:tornado.access:500 GET /raw-updates?queries=15 (172.16.98.98) 30093.22ms
ERROR:tornado.access:500 GET /raw-updates?queries=15 (172.16.98.98) 30094.34ms
2014-03-18 14:06:33 [10914] [CRITICAL] WORKER TIMEOUT (pid:11048)
2014-03-18 14:06:33 [10914] [CRITICAL] WORKER TIMEOUT (pid:11049)
2014-03-18 14:06:33 [10914] [CRITICAL] WORKER TIMEOUT (pid:11050)
2014-03-18 14:06:33 [10914] [CRITICAL] WORKER TIMEOUT (pid:11051)
2014-03-18 14:06:33 [10914] [CRITICAL] WORKER TIMEOUT (pid:11052)
2014-03-18 14:06:33 [10914] [CRITICAL] WORKER TIMEOUT (pid:11053)
2014-03-18 14:06:33 [10914] [CRITICAL] WORKER TIMEOUT (pid:11054)
2014-03-18 14:06:33 [10914] [CRITICAL] WORKER TIMEOUT (pid:11056)
2014-03-18 14:06:33 [10914] [CRITICAL] WORKER TIMEOUT (pid:11059)
2014-03-18 14:06:33 [10914] [CRITICAL] WORKER TIMEOUT (pid:11060)
ERROR:app:Exception on /raw-updates [GET]
Traceback (most recent call last):
  File "/home/tfb/FrameworkBenchmarks/installs/pypy/site-packages/Flask-0.10.1-py2.7.egg/flask/app.py", line 1817, in wsgi_app
    response = self.full_dispatch_request()
  File "/home/tfb/FrameworkBenchmarks/installs/pypy/site-packages/Flask-0.10.1-py2.7.egg/flask/app.py", line 1477, in full_dispatch_request
    rv = self.handle_user_exception(e)
  File "/home/tfb/FrameworkBenchmarks/installs/pypy/site-packages/Flask-0.10.1-py2.7.egg/flask/app.py", line 1381, in handle_user_exception
    reraise(exc_type, exc_value, tb)
  File "/home/tfb/FrameworkBenchmarks/installs/pypy/site-packages/Flask-0.10.1-py2.7.egg/flask/app.py", line 1475, in full_dispatch_request
    rv = self.dispatch_request()
  File "/home/tfb/FrameworkBenchmarks/installs/pypy/site-packages/Flask-0.10.1-py2.7.egg/flask/app.py", line 1461, in dispatch_request
    return self.view_functions[rule.endpoint](**req.view_args)
  File "/home/tfb/FrameworkBenchmarks/flask/app.py", line 152, in raw_updates
    (randomNumber, world['id']))
  File "/home/tfb/FrameworkBenchmarks/installs/pypy/site-packages/SQLAlchemy-0.8.3-py2.7.egg/sqlalchemy/engine/base.py", line 1613, in execute
    connection = self.contextual_connect(close_with_result=True)
  File "/home/tfb/FrameworkBenchmarks/installs/pypy/site-packages/SQLAlchemy-0.8.3-py2.7.egg/sqlalchemy/engine/base.py", line 1661, in contextual_connect
    self.pool.connect(),
  File "/home/tfb/FrameworkBenchmarks/installs/pypy/site-packages/SQLAlchemy-0.8.3-py2.7.egg/sqlalchemy/pool.py", line 272, in connect
    return _ConnectionFairy(self).checkout()
  File "/home/tfb/FrameworkBenchmarks/installs/pypy/site-packages/SQLAlchemy-0.8.3-py2.7.egg/sqlalchemy/pool.py", line 431, in __init__
    rec = self._connection_record = pool._do_get()
  File "/home/tfb/FrameworkBenchmarks/installs/pypy/site-packages/SQLAlchemy-0.8.3-py2.7.egg/sqlalchemy/pool.py", line 780, in _do_get
    (self.size(), self.overflow(), self._timeout))
TimeoutError: QueuePool limit of size 5 overflow 10 reached, connection timed out, timeout 30
ERROR:tornado.access:500 GET /raw-updates?queries=15 (172.16.98.98) 30094.47ms
2014-03-18 14:06:38 [10914] [CRITICAL] WORKER TIMEOUT (pid:11079)
2014-03-18 14:06:38 [10914] [CRITICAL] WORKER TIMEOUT (pid:11079)
ERROR:tornado.application:Uncaught exception, closing connection.
Traceback (most recent call last):
  File "/home/tfb/FrameworkBenchmarks/installs/pypy/site-packages/tornado-3.1-py2.7.egg/tornado/iostream.py", line 341, in wrapper
    callback(*args)
  File "/home/tfb/FrameworkBenchmarks/installs/pypy/site-packages/tornado-3.1-py2.7.egg/tornado/stack_context.py", line 331, in wrapped
    raise_exc_info(exc)
  File "/home/tfb/FrameworkBenchmarks/installs/pypy/site-packages/tornado-3.1-py2.7.egg/tornado/stack_context.py", line 302, in wrapped
    ret = fn(*args, **kwargs)
TypeError: exceptions must be old-style classes or derived from BaseException, not NoneType
ERROR:tornado.application:Uncaught exception, closing connection.
Traceback (most recent call last):
  File "/home/tfb/FrameworkBenchmarks/installs/pypy/site-packages/tornado-3.1-py2.7.egg/tornado/iostream.py", line 341, in wrapper
    callback(*args)
  File "/home/tfb/FrameworkBenchmarks/installs/pypy/site-packages/tornado-3.1-py2.7.egg/tornado/stack_context.py", line 331, in wrapped
    raise_exc_info(exc)
  File "/home/tfb/FrameworkBenchmarks/installs/pypy/site-packages/tornado-3.1-py2.7.egg/tornado/stack_context.py", line 302, in wrapped
    ret = fn(*args, **kwargs)
TypeError: exceptions must be old-style classes or derived from BaseException, not NoneType
ERROR:tornado.application:Uncaught exception, closing connection.
Traceback (most recent call last):
  File "/home/tfb/FrameworkBenchmarks/installs/pypy/site-packages/tornado-3.1-py2.7.egg/tornado/iostream.py", line 341, in wrapper
    callback(*args)
  File "/home/tfb/FrameworkBenchmarks/installs/pypy/site-packages/tornado-3.1-py2.7.egg/tornado/stack_context.py", line 331, in wrapped
    raise_exc_info(exc)
  File "/home/tfb/FrameworkBenchmarks/installs/pypy/site-packages/tornado-3.1-py2.7.egg/tornado/stack_context.py", line 302, in wrapped
    ret = fn(*args, **kwargs)
TypeError: exceptions must be old-style classes or derived from BaseException, not NoneType
ERROR:tornado.application:Uncaught exception, closing connection.
Traceback (most recent call last):
  File "/home/tfb/FrameworkBenchmarks/installs/pypy/site-packages/tornado-3.1-py2.7.egg/tornado/iostream.py", line 341, in wrapper
    callback(*args)
  File "/home/tfb/FrameworkBenchmarks/installs/pypy/site-packages/tornado-3.1-py2.7.egg/tornado/stack_context.py", line 331, in wrapped
    raise_exc_info(exc)
  File "/home/tfb/FrameworkBenchmarks/installs/pypy/site-packages/tornado-3.1-py2.7.egg/tornado/stack_context.py", line 302, in wrapped
    ret = fn(*args, **kwargs)
TypeError: exceptions must be old-style classes or derived from BaseException, not NoneType
Error in atexit._run_exitfuncs:
Traceback (most recent call last):
  File "/home/tfb/FrameworkBenchmarks/installs/pypy/lib-python/2.7/atexit.py", line 24, in _run_exitfuncs
    func(*targs, **kargs)
  File "/home/tfb/FrameworkBenchmarks/installs/pypy/lib-python/2.7/logging/__init__.py", line 1661, in shutdown
    h.release()
  File "/home/tfb/FrameworkBenchmarks/installs/pypy/lib-python/2.7/logging/__init__.py", line 717, in release
    self.lock.release()
  File "/home/tfb/FrameworkBenchmarks/installs/pypy/lib-python/2.7/threading.py", line 142, in release
    raise RuntimeError("cannot release un-acquired lock")
RuntimeError: cannot release un-acquired lock
Traceback (most recent call last):
  File "app_main.py", line 72, in run_toplevel
  File "/home/tfb/FrameworkBenchmarks/installs/pypy/lib-python/2.7/atexit.py", line 24, in _run_exitfuncs
    func(*targs, **kargs)
  File "/home/tfb/FrameworkBenchmarks/installs/pypy/lib-python/2.7/logging/__init__.py", line 1661, in shutdown
    h.release()
  File "/home/tfb/FrameworkBenchmarks/installs/pypy/lib-python/2.7/logging/__init__.py", line 717, in release
    self.lock.release()
  File "/home/tfb/FrameworkBenchmarks/installs/pypy/lib-python/2.7/threading.py", line 142, in release
    raise RuntimeError("cannot release un-acquired lock")
RuntimeError: cannot release un-acquired lock
